Workbook

Sheet Смета СН-2012 по гл. 1-5
A1: =CONCATENATE(Source!B1, " СН-2012 (© ОАО МЦЦС 'Мосстройцены', ", "2024", ")") -> Smeta.RU Flash (495) 974-1589 СН-2012 (© ОАО МЦЦС 'Мосстройцены', 2024)
J2: Форма № 1а (глава 1-5)
B3: "СОГЛАСОВАНО" | G3: "УТВЕРЖДАЮ"
B6: =CONCATENATE("______________________ ", IF(Source!AL12<>"", Source!AL12, "")) -> ______________________ | G6: =CONCATENATE("______________________ ", IF(Source!AH12<>"", Source!AH12, "")) -> ______________________
B7: "_____"________________ 2024 г. | G7: "_____"________________ 2024 г.
A10: =CONCATENATE( "ЛОКАЛЬНАЯ СМЕТА № ",IF(Source!F12<>"Новый объект", Source!F12, "")) -> ЛОКАЛЬНАЯ СМЕТА №
A11: (локальный сметный расчет)
A15: =IF(Source!G12<>"Новый объект", Source!G12, "") -> +Текущий ремонт спортзала №1 + раздевалки по адресу: г. Москва, ул. Митинская улица, д. 48, корп. 2 | AE15: =IF(Source!G12<>"Новый объект", Source!G12, "") -> +Текущий ремонт спортзала №1 + раздевалки по адресу: г. Москва, ул. Митинская улица, д. 48, корп. 2
A16: (наименование работ и затрат, наименование объекта)
A18: =CONCATENATE( "Основание: чертежи № ", Source!J12) -> Основание: чертежи №
F20: Сметная стоимость | I20: =I21+I22+I23+I24 -> 2116.77 | K20: тыс.руб
F21: Строительные работы | I21: =ROUND((Source!F539)/1000, 2) -> 0 | K21: тыс.руб
F22: Монтажные работы | I22: =ROUND((Source!F540)/1000, 2) -> 0 | K22: тыс.руб
F23: Оборудование | I23: =ROUND((Source!F531)/1000, 2) -> 0 | K23: тыс.руб
F24: Прочие работы | I24: =ROUND((Source!F541+Source!F542)/1000, 2) -> 2116.77 | K24: тыс.руб
F25: Средства на оплату труда | I25: =(Source!F537+ Source!F536)/1000 -> 609.91757 | K25: тыс.руб
A26: Составлен(а) в уровне текущих (прогнозных) цен на январь 2024 года
A27: №№ п/п | B27: Шифр расценки и коды ресурсов | C27: Наименование работ и затрат | D27: Единица измерения | E27: Кол-во единиц | F27: Цена на ед. изм. руб. | G27: Попра-вочные коэфф. | H27: Коэфф. зимних удоро-жаний | I27: Коэфф. пересчета | J27: ВСЕГО затрат, руб. | K27: Справочно
K28: ЗТР, всего чел.-час
K29: Ст-ть ед. с начислен.
A30: 1 | B30: 2 | C30: 3 | D30: 4 | E30: 5 | F30: 6 | G30: 7 | H30: 8 | I30: 9 | J30: 10 | K30: 11
A32: =CONCATENATE("Локальная смета: ",IF(Source!G20<>"Новая локальная смета", Source!G20, "")) -> Локальная смета:
A34: =CONCATENATE("Раздел: ",IF(Source!G24<>"Новый раздел", Source!G24, "")) -> Раздел: 1. Спортзал №1
A36: =CONCATENATE("Подраздел: ",IF(Source!G28<>"Новый подраздел", Source!G28, "")) -> Подраздел: 1.1 Демонтажные работы
A37: 1 | B37: =Source!F32 -> 1.1-3404-4-2/1 | C37: =Source!G32 -> Разборка плинтусов поливинилхлоридных с креплением шурупами | D37: =Source!H32 -> 100 м | E37: =Source!I32 -> 0.6504 | Q37: =ROUND((Source!BZ32/100)*ROUND((Source!AF32*Source!AV32)*Source!I32, 2), 2) -> 318.48 | R37: =Source!X32 -> 318.48 | S37: =ROUND((Source!CA32/100)*ROUND((Source!AF32*Source!AV32)*Source!I32, 2), 2) -> 45.5 | T37: =Source!Y32 -> 45.5 | U37: =ROUND((175/100)*ROUND((Source!AE32*Source!AV32)*Source!I32, 2), 2) -> 0 | V37: =ROUND((108/100)*ROUND(Source!CS32*Source!I32, 2), 2) -> 0
C38: ЗП | F38: =Source!AO32 -> 699.53 | G38: =Source!DG32 | H38: =Source!AV32 -> 1 | I38: =IF(Source!BA32<> 0, Source!BA32, 1) -> 1 | J38: =Source!S32 -> 454.97
C39: ЭМ | F39: =Source!AM32 -> 1.79 | G39: =Source!DE32 | H39: =Source!AV32 -> 1 | I39: =IF(Source!BB32<> 0, Source!BB32, 1) -> 1 | J39: =Source!Q32 -> 1.16
C40: НР от ЗП | D40: % | E40: =Source!AT32 -> 70 | J40: =SUM(R37:R39) -> 318.48
C41: СП от ЗП | D41: % | E41: =Source!AU32 -> 10 | J41: =SUM(T37:T40) -> 45.5
C42: ЗТР | D42: чел-ч | E42: =Source!AQ32 -> 2.78 | G42: =Source!DI32 | H42: =Source!AV32 -> 1 | K42: =Source!U32 -> 1.808112
I43: =J38+J39+J40+J41 -> 820.11 | K43: =IF(Source!I32<>0, ROUND(I43/Source!I32, 2), 0) -> 1260.93 | P43: =I43 -> 820.11
A44: 2 | B44: =Source!F33 -> 1.3-3204-1-1/1 | C44: =Source!G33 -> Расчистка поверхностей от старых покрасок (шпателем, щетками и т.д.) | D44: =Source!H33 -> м2 | E44: =Source!I33 -> 401.97 | Q44: =ROUND((Source!BZ33/100)*ROUND((Source!AF33*Source!AV33)*Source!I33, 2), 2) -> 41857.94 | R44: =Source!X33 -> 41857.94 | S44: =ROUND((Source!CA33/100)*ROUND((Source!AF33*Source!AV33)*Source!I33, 2), 2) -> 5979.71 | T44: =Source!Y33 -> 5979.71 | U44: =ROUND((175/100)*ROUND((Source!AE33*Source!AV33)*Source!I33, 2), 2) -> 0 | V44: =ROUND((108/100)*ROUND(Source!CS33*Source!I33, 2), 2) -> 0
C45: ="Объем: "&Source!I33&"=283,2+"&"118,77" -> Объем: 401,97=283,2+118,77
C46: ЗП | F46: =Source!AO33 -> 148.76 | G46: =Source!DG33 | H46: =Source!AV33 -> 1 | I46: =IF(Source!BA33<> 0, Source!BA33, 1) -> 1 | J46: =Source!S33 -> 59797.06
C47: НР от ЗП | D47: % | E47: =Source!AT33 -> 70 | J47: =SUM(R44:R46) -> 41857.94
C48: СП от ЗП | D48: % | E48: =Source!AU33 -> 10 | J48: =SUM(T44:T47) -> 5979.71
C49: ЗТР | D49: чел-ч | E49: =Source!AQ33 -> 0.6 | G49: =Source!DI33 | H49: =Source!AV33 -> 1 | K49: =Source!U33 -> 241.182
I50: =J46+J47+J48 -> 107634.71 | K50: =IF(Source!I33<>0, ROUND(I50/Source!I33, 2), 0) -> 267.77 | P50: =I50 -> 107634.71
A51: 3 | B51: =Source!F34 -> 1.1-3304-1-1/1 | C51: =Source!G34 -> Демонтаж радиатора массой до 80 кг | D51: =Source!H34 -> 100 шт. | E51: =Source!I34 -> 0.26 | Q51: =ROUND((Source!BZ34/100)*ROUND((Source!AF34*Source!AV34)*Source!I34, 2), 2) -> 5764.04 | R51: =Source!X34 -> 5764.04 | S51: =ROUND((Source!CA34/100)*ROUND((Source!AF34*Source!AV34)*Source!I34, 2), 2) -> 823.43 | T51: =Source!Y34 -> 823.43 | U51: =ROUND((175/100)*ROUND((Source!AE34*Source!AV34)*Source!I34, 2), 2) -> 0 | V51: =ROUND((108/100)*ROUND(Source!CS34*Source!I34, 2), 2) -> 0
C52: ЗП | F52: =Source!AO34 -> 31670.55 | G52: =Source!DG34 | H52: =Source!AV34 -> 1 | I52: =IF(Source!BA34<> 0, Source!BA34, 1) -> 1 | J52: =Source!S34 -> 8234.34
...

Sheet Дефектная ведомость
A1: =Source!B1 -> Smeta.RU Flash (495) 974-1589
D3: "УТВЕРЖДАЮ"
C5: ___________________________
C7: ___________________________
C9: " ___ " ___________ 20 ___ г.
A11: =CONCATENATE("Дефектный акт ", IF(Source!AN15<>"", Source!AN15," ")) -> Дефектный акт
A12: На Текущий ремонт спортзала №1 + раздевалки по адресу: г. Москва, ул. Митинская улица, д. 48, корп. 2 | AD12: =CONCATENATE("На капитальный ремонт ", Source!G12) -> На капитальный ремонт +Текущий ремонт спортзала №1 + раздевалки по адресу: г. Москва, ул. Митинская улица, д. 48, корп. 2
B14: Мы, нижеподписавшиеся, произвели осмотр объекта
B15: и постановили произвести ремонт объекта в
B16: следующем объеме:
A17: № п/п | B17: Наименование работ и затрат | C17: Единица измерения | D17: Количество | E17: Примечание
A18: 1 | B18: 2 | C18: 3 | D18: 4 | E18: 5
A19: =CONCATENATE("Локальная смета: ", Source!G20) -> Локальная смета: Новая локальная смета
A20: =CONCATENATE("Раздел: ", Source!G24) -> Раздел: 1. Спортзал №1
A21: =CONCATENATE("Подраздел: ", Source!G28) -> Подраздел: 1.1 Демонтажные работы
A22: 1 | B22: =Source!G32 -> Разборка плинтусов поливинилхлоридных с креплением шурупами | C22: =Source!H32 -> 100 м | D22: =Source!I32 -> 0.6504
A23: 2 | B23: =Source!G33 -> Расчистка поверхностей от старых покрасок (шпателем, щетками и т.д.) | C23: =Source!H33 -> м2 | D23: =Source!I33 -> 401.97
A24: 3 | B24: =Source!G34 -> Демонтаж радиатора массой до 80 кг | C24: =Source!H34 -> 100 шт. | D24: =Source!I34 -> 0.26
A25: 3.1 | B25: =Source!G35 -> Масса мусора | C25: =Source!H35 -> т | D25: =Source!I35 -> -2.08
A26: 4 | B26: =Source!G36 -> Устройство и разборка защитного ограждения лесов из сетки | C26: =Source!H36 -> 100 м2 | D26: =Source!I36 -> 0.776
A27: 5 | B27: =Source!G37 -> Разборка трубопроводов центрального отопления на сварке диаметром труб до 50 мм | C27: =Source!H37 -> 100 м | D27: =Source!I37 -> 0.4
A28: 5.1 | B28: =Source!G38 -> Масса мусора | C28: =Source!H38 -> т | D28: =Source!I38 -> -0.1816
A29: 6 | B29: =Source!G39 -> Вынос и занос мебели, в том числе спортивных снарядов массой до 50 кг | C29: =Source!H39 -> шт. | D29: =Source!I39 -> 15
A30: 7 | B30: =Source!G40 -> Монтаж мелких конструкций из стали различного профиля массой до 20 кг | C30: =Source!H40 -> т | D30: =Source!I40 -> 0.13744
A31: 8 | B31: =Source!G41 -> Пробивка отбойным молотком сквозных отверстий в бетонных стенах и фундаментах толщиной 0,4 м для трубопроводов диаметром 100 мм | C31: =Source!H41 -> 100 шт. | D31: =Source!I41 -> 0.05
A32: =CONCATENATE("Подраздел: ", Source!G73) -> Подраздел: 1.2 Ремонтно-строительные работы
A33: 9 | B33: =Source!G77 -> Простая штукатурка поверхностей стен по камню и бетону известковым раствором | C33: =Source!H77 -> 100 м2 | D33: =Source!I77 -> 3.9591
A34: 10 | B34: =Source!G78 -> Обработка поверхностей стен грунтовкой глубокого проникновения внутри помещения | C34: =Source!H78 -> 100 м2 | D34: =Source!I78 -> 3.9591
A35: 11 | B35: =Source!G79 -> Улучшенная окраска стен внутри помещений водно-дисперсионными акриловыми красками - краска моющаяся типа ВД-АК-210 | C35: =Source!H79 -> 100 м2 | D35: =Source!I79 -> 3.9591
A36: 12 | B36: =Source!G80 -> Установка и разборка инвентарных лесов внутренних трубчатых при высоте помещений до 6 м (без затрат по эксплуатации лесов) | C36: =Source!H80 -> 100 м2 | D36: =Source!I80 -> 2.837
A37: 13 | B37: =Source!G81 -> Простая штукатурка поверхностей потолков по камню и бетону известковым раствором | C37: =Source!H81 -> 100 м2 | D37: =Source!I81 -> 2.837
A38: 14 | B38: =Source!G82 -> Обработка поверхностей потолков грунтовкой глубокого проникновения внутри помещения | C38: =Source!H82 -> 100 м2 | D38: =Source!I82 -> 2.837
A39: 15 | B39: =Source!G83 -> Улучшенная окраска потолков внутри помещений водно-дисперсионными акриловыми красками - краска моющаяся типа ВД-АК-210 | C39: =Source!H83 -> 100 м2 | D39: =Source!I83 -> 2.837
A40: 16 | B40: =Source!G84 -> Устройство плинтусов - поливинилхлоридных на винтах самонарезающих с креплением через защёлку / с мягким краем, размеры 50-62х21 мм | C40: =Source!H84 -> 100 м | D40: =Source!I84 -> 0.6504
A41: 17 | B41: =Source!G85 -> Установка штучных изделий столов, шкафов под мойки, холодильных шкафов и др. (без стоимости изделий) | C41: =Source!H85 -> 100 шт. | D41: =Source!I85 -> 0.04
A42: 17.1 | B42: =Source!G86 -> Шведская стенка деревянная с турником 1x3 м или эквивалент | C42: =Source!H86 -> шт. | D42: =Source!I86 -> 4
A43: =CONCATENATE("Подраздел: ", Source!G118) -> Подраздел: 1.3 Сантехнические работы
A44: 18 | B44: =Source!G122 -> Установка радиаторов биметаллических "Рифар" / 10 секций, размеры 261х100х800 мм, теплоотдача 1010 Вт | C44: =Source!H122 -> 100 квт | D44: =Source!I122 -> 0.5096
A45: 18.1 | B45: =Source!G123 -> Радиаторы биметаллические секционные "Рифар", межосевое расстояние 200 мм, 10 секций, размеры 261х100х800 мм, теплоотдача 1010 Вт | C45: =Source!H123 -> шт. | D45: =Source!I123 -> -50.455496
A46: 18.2 | B46: =Source!G124 -> Радиатор Rifar Monolit 500/100 биметалл 10 секций или эквивалент | C46: =Source!H124 -> шт. | D46: =Source!I124 -> 26
...

Sheet RV_DATA
A1: BuildingFinished | B1: Trud | C1: Mash | D1: Mat | E1: MatZak | F1: Oborud | G1: OborudZak | H1: ZeroStoim | I1: NegativeKoll | J1: ReUnionKollResurcy | K1: UnionOneUchRes | L1: IdLevel | M1: ViewCodes | N1: UnionCodes | O1: PEREVOZKA
A2: 1 | B2: 0 | C2: 0 | D2: 1 | E2: 1 | F2: 1 | G2: 1 | H2: 0 | I2: 0 | J2: 0 | K2: 1 | L2: 72192302 | M2: 0 | N2: 0 | O2: 0
A4: TYPE | B4: SOURCE_LINK | C4: RABMAT_EX | D4: TIP_RAB | E4: TYPE_TRUD | F4: TAB | G4: NAME | H4: EDIZM | I4: KOLL | J4: UCH | K4: PRICE_B | L4: PRICE_ED | M4: STOIM_B | N4: PRICE_C | O4: STOIM_C | P4: ZPM_B | Q4: ZPM_ED | R4: STOIM_ZPM_B | S4: ZPM_C | T4: STOIM_ZPM_C | U4: RABMAT | V4: WBS | W4: CBSI | X4: CBSII | Y4: TechSpecCVORPP | Z4: CRC_GR_RES | AA4: CRC_B | AB4: CRC_C
A6: =Source!A20 -> 3 | B6: 20 | G6: =Source!G20 -> Новая локальная смета
A7: =Source!A24 -> 4 | B7: 24 | G7: =Source!G24 -> 1. Спортзал №1
A8: =Source!A28 -> 5 | B8: 28 | G8: =Source!G28 -> 1.1 Демонтажные работы
A9: =Source!A73 -> 5 | B9: 73 | G9: =Source!G73 -> 1.2 Ремонтно-строительные работы
A10: =Source!A86 -> 18 | B10: 86 | C10: 3 | D10: =Source!BI86 -> 4 | E10: =Source!FS86 -> 0 | F10: =Source!F86 -> Цена поставщика | G10: =Source!G86 -> Шведская стенка деревянная с турником 1x3 м или эквивалент | H10: =Source!H86 -> шт. | I10: =Source!I86 -> 4 | J10: 1 | K10: =Source!AC86 -> 8545.05 | M10: =ROUND(K10*I10, 2) -> 34180.2 | N10: =Source!AC86*IF(Source!BC86<> 0, Source!BC86, 1) -> 8545.05 | O10: =ROUND(N10*I10, 2) -> 34180.2 | P10: =Source!AE86 -> 0 | R10: =ROUND(P10*I10, 2) -> 0 | S10: =Source!AE86*IF(Source!BS86<> 0, Source!BS86, 1) -> 0 | T10: =ROUND(S10*I10, 2) -> 0 | U10: 3 | Z10: =Source!GF86 -> 1111623754 | AA10: 290821961 | AB10: 290821961
A11: =Source!A118 -> 5 | B11: 118 | G11: =Source!G118 -> 1.3 Сантехнические работы
A12: =Source!A124 -> 18 | B12: 124 | C12: 3 | D12: =Source!BI124 -> 4 | E12: =Source!FS124 -> 0 | F12: =Source!F124 -> Цена поставщика | G12: =Source!G124 -> Радиатор Rifar Monolit 500/100 биметалл 10 секций или эквивалент | H12: =Source!H124 -> шт. | I12: =Source!I124 -> 26 | J12: 1 | K12: =Source!AC124 -> 12673.5 | M12: =ROUND(K12*I12, 2) -> 329511 | N12: =Source!AC124*IF(Source!BC124<> 0, Source!BC124, 1) -> 12673.5 | O12: =ROUND(N12*I12, 2) -> 329511 | P12: =Source!AE124 -> 0 | R12: =ROUND(P12*I12, 2) -> 0 | S12: =Source!AE124*IF(Source!BS124<> 0, Source!BS124, 1) -> 0 | T12: =ROUND(S12*I12, 2) -> 0 | U12: 3 | Z12: =Source!GF124 -> 195406401 | AA12: 549507648 | AB12: 549507648
A13: =Source!A126 -> 18 | B13: 126 | C13: 3 | D13: =Source!BI126 -> 4 | E13: =Source!FS126 -> 0 | F13: =Source!F126 -> 21.12-10-45 | G13: =Source!G126 -> Кронштейны для крепления отопительных приборов, марка КРД, длина 131 мм | H13: =Source!H126 -> шт. | I13: =Source!I126 -> 52 | J13: 1 | K13: =Source!AC126 -> 51.23 | M13: =ROUND(K13*I13, 2) -> 2663.96 | N13: =Source!AC126*IF(Source!BC126<> 0, Source!BC126, 1) -> 51.23 | O13: =ROUND(N13*I13, 2) -> 2663.96 | P13: =Source!AE126 -> 0 | R13: =ROUND(P13*I13, 2) -> 0 | S13: =Source!AE126*IF(Source!BS126<> 0, Source!BS126, 1) -> 0 | T13: =ROUND(S13*I13, 2) -> 0 | U13: 3 | Z13: =Source!GF126 -> 140294319 | AA13: 196322037 | AB13: 196322037
A14: =Source!A130 -> 18 | B14: 130 | C14: 3 | D14: =Source!BI130 -> 4 | E14: =Source!FS130 -> 0 | F14: =Source!F130 -> 21.3-4-19 | G14: =Source!G130 -> Арматурные заготовки (стержни, хомуты и т.п.), не собранные в каркасы или сетки, арматурная сталь периодического профиля, класс А-III, диаметр 20-22 мм | H14: =Source!H130 -> т | I14: =Source!I130 -> 0.0729 | J14: 1 | K14: =Source!AC130 -> 71207.52 | M14: =ROUND(K14*I14, 2) -> 5191.03 | N14: =Source!AC130*IF(Source!BC130<> 0, Source!BC130, 1) -> 71207.52 | O14: =ROUND(N14*I14, 2) -> 5191.03 | P14: =Source!AE130 -> 0 | R14: =ROUND(P14*I14, 2) -> 0 | S14: =Source!AE130*IF(Source!BS130<> 0, Source!BS130, 1) -> 0 | T14: =ROUND(S14*I14, 2) -> 0 | U14: 3 | Z14: =Source!GF130 -> 1622126655 | AA14: -1439171684 | AB14: -1439171684
A15: =Source!A132 -> 18 | B15: 132 | C15: 3 | D15: =Source!BI132 -> 4 | E15: =Source!FS132 -> 0 | F15: =Source!F132 -> 21.3-4-19 | G15: =Source!G132 -> Арматурные заготовки (стержни, хомуты и т.п.), не собранные в каркасы или сетки, арматурная сталь периодического профиля, класс А-III, диаметр 20-22 мм | H15: =Source!H132 -> т | I15: =Source!I132 -> 0.0405 | J15: 1 | K15: =Source!AC132 -> 71207.52 | M15: =ROUND(K15*I15, 2) -> 2883.9 | N15: =Source!AC132*IF(Source!BC132<> 0, Source!BC132, 1) -> 71207.52 | O15: =ROUND(N15*I15, 2) -> 2883.9 | P15: =Source!AE132 -> 0 | R15: =ROUND(P15*I15, 2) -> 0 | S15: =Source!AE132*IF(Source!BS132<> 0, Source!BS132, 1) -> 0 | T15: =ROUND(S15*I15, 2) -> 0 | U15: 3 | Z15: =Source!GF132 -> 1622126655 | AA15: -1439171684 | AB15: -1439171684
A16: =Source!A135 -> 18 | B16: 135 | C16: 3 | D16: =Source!BI135 -> 4 | E16: =Source!FS135 -> 0 | F16: =Source!F135 -> Цена поставщика | G16: =Source!G135 -> Кран шаровой Ду 20 Бугатти или эквивалент | H16: =Source!H135 -> шт. | I16: =Source!I135 -> 10 | J16: 1 | K16: =Source!AC135 -> 544 | M16: =ROUND(K16*I16, 2) -> 5440 | N16: =Source!AC135*IF(Source!BC135<> 0, Source!BC135, 1) -> 544 | O16: =ROUND(N16*I16, 2) -> 5440 | P16: =Source!AE135 -> 0 | R16: =ROUND(P16*I16, 2) -> 0 | S16: =Source!AE135*IF(Source!BS135<> 0, Source!BS135, 1) -> 0 | T16: =ROUND(S16*I16, 2) -> 0 | U16: 3 | Z16: =Source!GF135 -> 502732464 | AA16: 1765282897 | AB16: 1765282897
A17: =Source!A137 -> 18 | B17: 137 | C17: 3 | D17: =Source!BI137 -> 4 | E17: =Source!FS137 -> 0 | F17: =Source!F137 -> Цена поставщика | G17: =Source!G137 -> Кран шаровой Ду 25 Бугатти или эквивалент | H17: =Source!H137 -> шт. | I17: =Source!I137 -> 4 | J17: 1 | K17: =Source!AC137 -> 1471.35 | M17: =ROUND(K17*I17, 2) -> 5885.4 | N17: =Source!AC137*IF(Source!BC137<> 0, Source!BC137, 1) -> 1471.35 | O17: =ROUND(N17*I17, 2) -> 5885.4 | P17: =Source!AE137 -> 0 | R17: =ROUND(P17*I17, 2) -> 0 | S17: =Source!AE137*IF(Source!BS137<> 0, Source!BS137, 1) -> 0 | T17: =ROUND(S17*I17, 2) -> 0 | U17: 3 | Z17: =Source!GF137 -> 1738626795 | AA17: -1886084189 | AB17: -1886084189
A18: =Source!A170 -> 5 | B18: 170 | G18: =Source!G170 -> 1.4 Электромонтажные работы
A19: =Source!A179 -> 18 | B19: 179 | C19: 3 | D19: =Source!BI179 -> 4 | E19: =Source!FS179 -> 0 | F19: =Source!F179 -> 21.23-8-269 | G19: =Source!G179 -> Кабели силовые, с медными жилами, с изоляц. и оболоч.из ПВХ пластиката пониж.пожар.опасности, не распростр.горение, с пониж.дымо- и газовыделением и с низк.токсич-тью продуктов горения, напряж.1000 В, марка ВВГнг(А)-LSLTx, число жил и сечение, мм2: 3х1,5 | H19: =Source!H179 -> км | I19: =Source!I179 -> 0.0362 | J19: 1 | K19: =Source!AC179 -> 100115.51 | M19: =ROUND(K19*I19, 2) -> 3624.18 | N19: =Source!AC179*IF(Source!BC179<> 0, Source!BC179, 1) -> 100115.51 | O19: =ROUND(N19*I19, 2) -> 3624.18 | P19: =Source!AE179 -> 0 | R19: =ROUND(P19*I19, 2) -> 0 | S19: =Source!AE179*IF(Source!BS179<> 0, Source!BS179, 1) -> 0 | T19: =ROUND(S19*I19, 2) -> 0 | U19: 3 | Z19: =Source!GF179 -> 918109215 | AA19: 688701120 | AB19: 688701120
A20: =Source!A181 -> 18 | B20: 181 | C20: 3 | D20: =Source!BI181 -> 4 | E20: =Source!FS181 -> 0 | F20: =Source!F181 -> 21.21-5-24 | G20: =Source!G181 -> Выключатели, серия "Прима", напряжение 250 В, сила тока 6 А, тип: А16-051, одноклавишный, открытой установки | H20: =Source!H181 -> шт. | I20: =Source!I181 -> 1 | J20: 1 | K20: =Source!AC181 -> 39.99 | M20: =ROUND(K20*I20, 2) -> 39.99 | N20: =Source!AC181*IF(Source!BC181<> 0, Source!BC181, 1) -> 39.99 | O20: =ROUND(N20*I20, 2) -> 39.99 | P20: =Source!AE181 -> 0 | R20: =ROUND(P20*I20, 2) -> 0 | S20: =Source!AE181*IF(Source!BS181<> 0, Source!BS181, 1) -> 0 | T20: =ROUND(S20*I20, 2) -> 0 | U20: 3 | Z20: =Source!GF181 -> -1721790415 | AA20: -275146849 | AB20: -275146849
A21: =Source!A182 -> 18 | B21: 182 | C21: 3 | D21: =Source!BI182 -> 4 | E21: =Source!FS182 -> 0 | F21: =Source!F182 -> 21.21-5-25 | G21: =Source!G182 -> Выключатели серии "Прима", напряжение 250 В, сила тока 6 А, открытой установки двухклавишные, тип А56-029 | H21: =Source!H182 -> шт. | I21: =Source!I182 -> 1 | J21: 1 | K21: =Source!AC182 -> 102.63 | M21: =ROUND(K21*I21, 2) -> 102.63 | N21: =Source!AC182*IF(Source!BC182<> 0, Source!BC182, 1) -> 102.63 | O21: =ROUND(N21*I21, 2) -> 102.63 | P21: =Source!AE182 -> 0 | R21: =ROUND(P21*I21, 2) -> 0 | S21: =Source!AE182*IF(Source!BS182<> 0, Source!BS182, 1) -> 0 | T21: =ROUND(S21*I21, 2) -> 0 | U21: 3 | Z21: =Source!GF182 -> 154001895 | AA21: 598563480 | AB21: 598563480
A22: =Source!A184 -> 18 | B22: 184 | C22: 3 | D22: =Source!BI184 -> 4 | E22: =Source!FS184 -> 0 | F22: =Source!F184 -> Цена поставщика | G22: =Source!G184 -> Светильник светодиодный Geniled ЛПО 1200х180х40мм 40Вт 4000К Опал или эквивалент | H22: =Source!H184 -> шт. | I22: =Source!I184 -> 56 | J22: 1 | K22: =Source!AC184 -> 3323.5 | M22: =ROUND(K22*I22, 2) -> 186116 | N22: =Source!AC184*IF(Source!BC184<> 0, Source!BC184, 1) -> 3323.5 | O22: =ROUND(N22*I22, 2) -> 186116 | P22: =Source!AE184 -> 0 | R22: =ROUND(P22*I22, 2) -> 0 | S22: =Source!AE184*IF(Source!BS184<> 0, Source!BS184, 1) -> 0 | T22: =ROUND(S22*I22, 2) -> 0 | U22: 3 | Z22: =Source!GF184 -> -1650221762 | AA22: -915922714 | AB22: -915922714
A23: =Source!A185 -> 18 | B23: 185 | C23: 3 | D23: =Source!BI185 -> 4 | E23: =Source!FS185 -> 0 | F23: =Source!F185 -> Цена поставщика | G23: =Source!G185 -> Светильник светодиодный Geniled ЛПО 1200х180х40мм 40Вт 4000К Опал БАП или эквивалент | H23: =Source!H185 -> шт. | I23: =Source!I185 -> 8 | J23: 1 | K23: =Source!AC185 -> 5321 | M23: =ROUND(K23*I23, 2) -> 42568 | N23: =Source!AC185*IF(Source!BC185<> 0, Source!BC185, 1) -> 5321 | O23: =ROUND(N23*I23, 2) -> 42568 | P23: =Source!AE185 -> 0 | R23: =ROUND(P23*I23, 2) -> 0 | S23: =Source!AE185*IF(Source!BS185<> 0, Source!BS185, 1) -> 0 | T23: =ROUND(S23*I23, 2) -> 0 | U23: 3 | Z23: =Source!GF185 -> -1747291611 | AA23: -209616135 | AB23: -209616135
A24: =Source!A247 -> 4 | B24: 247 | G24: =Source!G247 -> 2. Тренерская
A25: =Source!A251 -> 5 | B25: 251 | G25: =Source!G251 -> 2.1 Тренерская
A26: =Source!A294 -> 5 | B26: 294 | G26: =Source!G294 -> 2.2 Ремонтно-строительные работы
A27: =Source!A336 -> 5 | B27: 336 | G27: =Source!G336 -> 2.3 Сантехнические работы
A28: =Source!A342 -> 18 | B28: 342 | C28: 3 | D28: =Source!BI342 -> 4 | E28: =Source!FS342 -> 0 | F28: =Source!F342 -> Цена поставщика | G28: =Source!G342 -> Радиатор Rifar Monolit 500/100 биметалл 10 секций или эквивалент | H28: =Source!H342 -> шт. | I28: =Source!I342 -> 3 | J28: 1 | K28: =Source!AC342 -> 12673.5 | M28: =ROUND(K28*I28, 2) -> 38020.5 | N28: =Source!AC342*IF(Source!BC342<> 0, Source!BC342, 1) -> 12673.5 | O28: =ROUND(N28*I28, 2) -> 38020.5 | P28: =Source!AE342 -> 0 | R28: =ROUND(P28*I28, 2) -> 0 | S28: =Source!AE342*IF(Source!BS342<> 0, Source!BS342, 1) -> 0 | T28: =ROUND(S28*I28, 2) -> 0 | U28: 3 | Z28: =Source!GF342 -> 195406401 | AA28: 549507648 | AB28: 549507648
A29: =Source!A344 -> 18 | B29: 344 | C29: 3 | D29: =Source!BI344 -> 4 | E29: =Source!FS344 -> 0 | F29: =Source!F344 -> 21.12-10-45 | G29: =Source!G344 -> Кронштейны для крепления отопительных приборов, марка КРД, длина 131 мм | H29: =Source!H344 -> шт. | I29: =Source!I344 -> 6 | J29: 1 | K29: =Source!AC344 -> 51.23 | M29: =ROUND(K29*I29, 2) -> 307.38 | N29: =Source!AC344*IF(Source!BC344<> 0, Source!BC344, 1) -> 51.23 | O29: =ROUND(N29*I29, 2) -> 307.38 | P29: =Source!AE344 -> 0 | R29: =ROUND(P29*I29, 2) -> 0 | S29: =Source!AE344*IF(Source!BS344<> 0, Source!BS344, 1) -> 0 | T29: =ROUND(S29*I29, 2) -> 0 | U29: 3 | Z29: =Source!GF344 -> 140294319 | AA29: 196322037 | AB29: 196322037
A30: =Source!A346 -> 18 | B30: 346 | C30: 3 | D30: =Source!BI346 -> 4 | E30: =Source!FS346 -> 0 | F30: =Source!F346 -> 21.3-4-19 | G30: =Source!G346 -> Арматурные заготовки (стержни, хомуты и т.п.), не собранные в каркасы или сетки, арматурная сталь периодического профиля, класс А-III, диаметр 20-22 мм | H30: =Source!H346 -> т | I30: =Source!I346 -> 0.02025 | J30: 1 | K30: =Source!AC346 -> 71207.52 | M30: =ROUND(K30*I30, 2) -> 1441.95 | N30: =Source!AC346*IF(Source!BC346<> 0, Source!BC346, 1) -> 71207.52 | O30: =ROUND(N30*I30, 2) -> 1441.95 | P30: =Source!AE346 -> 0 | R30: =ROUND(P30*I30, 2) -> 0 | S30: =Source!AE346*IF(Source!BS346<> 0, Source!BS346, 1) -> 0 | T30: =ROUND(S30*I30, 2) -> 0 | U30: 3 | Z30: =Source!GF346 -> 1622126655 | AA30: -1439171684 | AB30: -1439171684
A31: =Source!A349 -> 18 | B31: 349 | C31: 3 | D31: =Source!BI349 -> 4 | E31: =Source!FS349 -> 0 | F31: =Source!F349 -> Цена поставщика | G31: =Source!G349 -> Кран шаровой Ду 20 Бугатти или эквивалент | H31: =Source!H349 -> шт. | I31: =Source!I349 -> 7 | J31: 1 | K31: =Source!AC349 -> 544 | M31: =ROUND(K31*I31, 2) -> 3808 | N31: =Source!AC349*IF(Source!BC349<> 0, Source!BC349, 1) -> 544 | O31: =ROUND(N31*I31, 2) -> 3808 | P31: =Source!AE349 -> 0 | R31: =ROUND(P31*I31, 2) -> 0 | S31: =Source!AE349*IF(Source!BS349<> 0, Source!BS349, 1) -> 0 | T31: =ROUND(S31*I31, 2) -> 0 | U31: 3 | Z31: =Source!GF349 -> 502732464 | AA31: 1765282897 | AB31: 1765282897
A32: =Source!A381 -> 5 | B32: 381 | G32: =Source!G381 -> 2.4 Электромонтажные работы
A33: =Source!A387 -> 18 | B33: 387 | C33: 3 | D33: =Source!BI387 -> 4 | E33: =Source!FS387 -> 0 | F33: =Source!F387 -> 21.21-5-25 | G33: =Source!G387 -> Выключатели серии "Прима", напряжение 250 В, сила тока 6 А, открытой установки двухклавишные, тип А56-029 | H33: =Source!H387 -> шт. | I33: =Source!I387 -> 2 | J33: 1 | K33: =Source!AC387 -> 102.63 | M33: =ROUND(K33*I33, 2) -> 205.26 | N33: =Source!AC387*IF(Source!BC387<> 0, Source!BC387, 1) -> 102.63 | O33: =ROUND(N33*I33, 2) -> 205.26 | P33: =Source!AE387 -> 0 | R33: =ROUND(P33*I33, 2) -> 0 | S33: =Source!AE387*IF(Source!BS387<> 0, Source!BS387, 1) -> 0 | T33: =ROUND(S33*I33, 2) -> 0 | U33: 3 | Z33: =Source!GF387 -> 154001895 | AA33: 598563480 | AB33: 598563480
A34: =Source!A390 -> 18 | B34: 390 | C34: 3 | D34: =Source!BI390 -> 4 | E34: =Source!FS390 -> 0 | F34: =Source!F390 -> 21.23-8-269 | G34: =Source!G390 -> Кабели силовые, с медными жилами, с изоляц. и оболоч.из ПВХ пластиката пониж.пожар.опасности, не распростр.горение, с пониж.дымо- и газовыделением и с низк.токсич-тью продуктов горения, напряж.1000 В, марка ВВГнг(А)-LSLTx, число жил и сечение, мм2: 3х1,5 | H34: =Source!H390 -> км | I34: =Source!I390 -> 0.0102 | J34: 1 | K34: =Source!AC390 -> 100115.51 | M34: =ROUND(K34*I34, 2) -> 1021.18 | N34: =Source!AC390*IF(Source!BC390<> 0, Source!BC390, 1) -> 100115.51 | O34: =ROUND(N34*I34, 2) -> 1021.18 | P34: =Source!AE390 -> 0 | R34: =ROUND(P34*I34, 2) -> 0 | S34: =Source!AE390*IF(Source!BS390<> 0, Source!BS390, 1) -> 0 | T34: =ROUND(S34*I34, 2) -> 0 | U34: 3 | Z34: =Source!GF390 -> 918109215 | AA34: 688701120 | AB34: 688701120
A35: =Source!A392 -> 18 | B35: 392 | C35: 3 | D35: =Source!BI392 -> 4 | E35: =Source!FS392 -> 0 | F35: =Source!F392 -> Цена поставщика | G35: =Source!G392 -> Светильник GENILED офис, потребляемая мощность 40 Вт, световой поток 4000 Лм, цветовая температура 5000 К, степень защиты IP20, габаритные размеры 595х595х20 мм или эквивалент | H35: =Source!H392 -> шт. | I35: =Source!I392 -> 6 | J35: 1 | K35: =Source!AC392 -> 3570 | M35: =ROUND(K35*I35, 2) -> 21420 | N35: =Source!AC392*IF(Source!BC392<> 0, Source!BC392, 1) -> 3570 | O35: =ROUND(N35*I35, 2) -> 21420 | P35: =Source!AE392 -> 0 | R35: =ROUND(P35*I35, 2) -> 0 | S35: =Source!AE392*IF(Source!BS392<> 0, Source!BS392, 1) -> 0 | T35: =ROUND(S35*I35, 2) -> 0 | U35: 3 | Z35: =Source!GF392 -> 515220028 | AA35: -1554945508 | AB35: -1554945508
A36: =Source!A454 -> 4 | B36: 454 | G36: =Source!G454 -> 3. Вывоз мусора
A37: 999

Sheet Расчет стоимости ресурсов
A2: Ресурсная ведомость на
A3: =CONCATENATE("Объект: ",IF(Source!G522<>"Новый объект", Source!G522, "")) -> Объект: +Текущий ремонт спортзала №1 + раздевалки по адресу: г. Москва, ул. Митинская улица, д. 48, корп. 2 | O3: Объект: +Текущий ремонт спортзала №1 + раздевалки по адресу: г. Москва, ул. Митинская улица, д. 48, корп. 2
A4: Обоснование | B4: Наименование | C4: Единица измерения | D4: Объем | E4: Текущая
E6: цена | F6: стоимость
A7: 1 | B7: 2 | C7: 3 | D7: 4 | E7: 5 | F7: 6
A8: =CONCATENATE("Локальная смета: ",IF(Source!G22<>"Новая локальная смета", Source!G22, "")) -> Локальная смета:
A9: =CONCATENATE("Раздел: ",IF(Source!G26<>"Новый раздел", Source!G26, "")) -> Раздел: 1. Спортзал №1
A10: =CONCATENATE("Подраздел: ",IF(Source!G30<>"Новый подраздел", Source!G30, "")) -> Подраздел: 1.1 Демонтажные работы
A11: =CONCATENATE("Подраздел: ",IF(Source!G75<>"Новый подраздел", Source!G75, "")) -> Подраздел: 1.2 Ремонтно-строительные работы
A12: Материальные ресурсы
A13: Цена поставщика | B13: Шведская стенка деревянная с турником 1x3 м | C13: шт. | D13: =ROUND(SUMIF(RV_DATA!AB10:AB10, 290821961, RV_DATA!I10:I10), 6) -> 4 | E13: =ROUND(RV_DATA!N10, 6) -> 8545.05 | F13: =ROUND(SUMIF(RV_DATA!AB10:AB10, 290821961, RV_DATA!O10:O10), 6) -> 34180.2 | Q13: 3
A14: Итого материальные ресурсы | E14: =SUMIF(Q13:Q13, 3, F13:F13) -> 34180.2
A15: =CONCATENATE("Подраздел: ",IF(Source!G120<>"Новый подраздел", Source!G120, "")) -> Подраздел: 1.3 Сантехнические работы
A16: Материальные ресурсы
A17: 21.12-10-45 | B17: Кронштейны для крепления отопительных приборов, марка КРД, длина 131 мм | C17: шт. | D17: =ROUND(SUMIF(RV_DATA!AB12:AB17, 196322037, RV_DATA!I12:I17), 6) -> 52 | E17: =ROUND(RV_DATA!N13, 6) -> 51.23 | F17: =ROUND(SUMIF(RV_DATA!AB12:AB17, 196322037, RV_DATA!O12:O17), 6) -> 2663.96 | Q17: 3
A18: 21.3-4-19 | B18: Арматурные заготовки (стержни, хомуты и т.п.), не собранные в каркасы или сетки, арматурная сталь периодического профиля, класс А-III, диаметр 20-22 мм | C18: т | D18: =ROUND(SUMIF(RV_DATA!AB12:AB17, -1439171684, RV_DATA!I12:I17), 6) -> 0.1134 | E18: =ROUND(RV_DATA!N14, 6) -> 71207.52 | F18: =ROUND(SUMIF(RV_DATA!AB12:AB17, -1439171684, RV_DATA!O12:O17), 6) -> 8074.93 | Q18: 3
A19: Цена поставщика | B19: Радиатор Rifar Monolit 500/100 биметалл 10 секций | C19: шт. | D19: =ROUND(SUMIF(RV_DATA!AB12:AB17, 549507648, RV_DATA!I12:I17), 6) -> 26 | E19: =ROUND(RV_DATA!N12, 6) -> 12673.5 | F19: =ROUND(SUMIF(RV_DATA!AB12:AB17, 549507648, RV_DATA!O12:O17), 6) -> 329511 | Q19: 3
A20: Цена поставщика | B20: Кран шаровой Ду 20 Бугатти | C20: шт. | D20: =ROUND(SUMIF(RV_DATA!AB12:AB17, 1765282897, RV_DATA!I12:I17), 6) -> 10 | E20: =ROUND(RV_DATA!N16, 6) -> 544 | F20: =ROUND(SUMIF(RV_DATA!AB12:AB17, 1765282897, RV_DATA!O12:O17), 6) -> 5440 | Q20: 3
A21: Цена поставщика | B21: Кран шаровой Ду 25 Бугатти | C21: шт. | D21: =ROUND(SUMIF(RV_DATA!AB12:AB17, -1886084189, RV_DATA!I12:I17), 6) -> 4 | E21: =ROUND(RV_DATA!N17, 6) -> 1471.35 | F21: =ROUND(SUMIF(RV_DATA!AB12:AB17, -1886084189, RV_DATA!O12:O17), 6) -> 5885.4 | Q21: 3
A22: Итого материальные ресурсы | E22: =SUMIF(Q17:Q21, 3, F17:F21) -> 351575.29
A23: =CONCATENATE("Подраздел: ",IF(Source!G172<>"Новый подраздел", Source!G172, "")) -> Подраздел: 1.4 Электромонтажные работы
A24: Материальные ресурсы
A25: 21.21-5-24 | B25: Выключатели, серия "Прима", напряжение 250 В, сила тока 6 А, тип: А16-051, одноклавишный, открытой установки | C25: шт. | D25: =ROUND(SUMIF(RV_DATA!AB19:AB23, -275146849, RV_DATA!I19:I23), 6) -> 1 | E25: =ROUND(RV_DATA!N20, 6) -> 39.99 | F25: =ROUND(SUMIF(RV_DATA!AB19:AB23, -275146849, RV_DATA!O19:O23), 6) -> 39.99 | Q25: 3
A26: 21.21-5-25 | B26: Выключатели серии "Прима", напряжение 250 В, сила тока 6 А, открытой установки двухклавишные, тип А56-029 | C26: шт. | D26: =ROUND(SUMIF(RV_DATA!AB19:AB23, 598563480, RV_DATA!I19:I23), 6) -> 1 | E26: =ROUND(RV_DATA!N21, 6) -> 102.63 | F26: =ROUND(SUMIF(RV_DATA!AB19:AB23, 598563480, RV_DATA!O19:O23), 6) -> 102.63 | Q26: 3
A27: 21.23-8-269 | B27: Кабели силовые, с медными жилами, с изоляц. и оболоч.из ПВХ пластиката пониж.пожар.опасности, не распростр.горение, с пониж.дымо- и газовыделением и с низк.токсич-тью продуктов горения, напряж.1000 В, марка ВВГнг(А)-LSLTx, число жил и сечение, мм2: 3х1,5 | C27: км | D27: =ROUND(SUMIF(RV_DATA!AB19:AB23, 688701120, RV_DATA!I19:I23), 6) -> 0.0362 | E27: =ROUND(RV_DATA!N19, 6) -> 100115.51 | F27: =ROUND(SUMIF(RV_DATA!AB19:AB23, 688701120, RV_DATA!O19:O23), 6) -> 3624.18 | Q27: 3
A28: Цена поставщика | B28: Светильник светодиодный Geniled ЛПО 1200х180х40мм 40Вт 4000К Опал | C28: шт. | D28: =ROUND(SUMIF(RV_DATA!AB19:AB23, -915922714, RV_DATA!I19:I23), 6) -> 56 | E28: =ROUND(RV_DATA!N22, 6) -> 3323.5 | F28: =ROUND(SUMIF(RV_DATA!AB19:AB23, -915922714, RV_DATA!O19:O23), 6) -> 186116 | Q28: 3
A29: Цена поставщика | B29: Светильник светодиодный Geniled ЛПО 1200х180х40мм 40Вт 4000К Опал БАП | C29: шт. | D29: =ROUND(SUMIF(RV_DATA!AB19:AB23, -209616135, RV_DATA!I19:I23), 6) -> 8 | E29: =ROUND(RV_DATA!N23, 6) -> 5321 | F29: =ROUND(SUMIF(RV_DATA!AB19:AB23, -209616135, RV_DATA!O19:O23), 6) -> 42568 | Q29: 3
A30: Итого материальные ресурсы | E30: =SUMIF(Q25:Q29, 3, F25:F29) -> 232450.8
A31: =CONCATENATE("Раздел: ",IF(Source!G249<>"Новый раздел", Source!G249, "")) -> Раздел: 2. Тренерская
A32: =CONCATENATE("Подраздел: ",IF(Source!G253<>"Новый подраздел", Source!G253, "")) -> Подраздел: 2.1 Тренерская
A33: =CONCATENATE("Подраздел: ",IF(Source!G296<>"Новый подраздел", Source!G296, "")) -> Подраздел: 2.2 Ремонтно-строительные работы
A34: =CONCATENATE("Подраздел: ",IF(Source!G338<>"Новый подраздел", Source!G338, "")) -> Подраздел: 2.3 Сантехнические работы
A35: Материальные ресурсы
A36: 21.12-10-45 | B36: Кронштейны для крепления отопительных приборов, марка КРД, длина 131 мм | C36: шт. | D36: =ROUND(SUMIF(RV_DATA!AB28:AB31, 196322037, RV_DATA!I28:I31), 6) -> 6 | E36: =ROUND(RV_DATA!N29, 6) -> 51.23 | F36: =ROUND(SUMIF(RV_DATA!AB28:AB31, 196322037, RV_DATA!O28:O31), 6) -> 307.38 | Q36: 3
A37: 21.3-4-19 | B37: Арматурные заготовки (стержни, хомуты и т.п.), не собранные в каркасы или сетки, арматурная сталь периодического профиля, класс А-III, диаметр 20-22 мм | C37: т | D37: =ROUND(SUMIF(RV_DATA!AB28:AB31, -1439171684, RV_DATA!I28:I31), 6) -> 0.02025 | E37: =ROUND(RV_DATA!N30, 6) -> 71207.52 | F37: =ROUND(SUMIF(RV_DATA!AB28:AB31, -1439171684, RV_DATA!O28:O31), 6) -> 1441.95 | Q37: 3
A38: Цена поставщика | B38: Радиатор Rifar Monolit 500/100 биметалл 10 секций | C38: шт. | D38: =ROUND(SUMIF(RV_DATA!AB28:AB31, 549507648, RV_DATA!I28:I31), 6) -> 3 | E38: =ROUND(RV_DATA!N28, 6) -> 12673.5 | F38: =ROUND(SUMIF(RV_DATA!AB28:AB31, 549507648, RV_DATA!O28:O31), 6) -> 38020.5 | Q38: 3
A39: Цена поставщика | B39: Кран шаровой Ду 20 Бугатти | C39: шт. | D39: =ROUND(SUMIF(RV_DATA!AB28:AB31, 1765282897, RV_DATA!I28:I31), 6) -> 7 | E39: =ROUND(RV_DATA!N31, 6) -> 544 | F39: =ROUND(SUMIF(RV_DATA!AB28:AB31, 1765282897, RV_DATA!O28:O31), 6) -> 3808 | Q39: 3
A40: Итого материальные ресурсы | E40: =SUMIF(Q36:Q39, 3, F36:F39) -> 43577.83
A41: =CONCATENATE("Подраздел: ",IF(Source!G383<>"Новый подраздел", Source!G383, "")) -> Подраздел: 2.4 Электромонтажные работы
A42: Материальные ресурсы
...

Sheet Source
A1: 0 | B1: Smeta.RU Flash (495) 974-1589 | D1: _PS_ | F1: 0 | G1: 0 | H1: 0 | I1: Smeta.RU Flash | K1: 1 | L1: 62169 | M1: 10 | N1: 11 | O1: 8 | P1: 0 | Q1: 0
A12: 1 | B12: 581 | C12: 0 | D12: =ROW(A522) -> 522 | E12: 0 | F12: Новый объект | G12: +Текущий ремонт спортзала №1 + раздевалки по адресу: г. Москва, ул. Митинская улица, д. 48, корп. 2 | I12: 0 | K12: 0 | L12: 0 | M12: 2 | O12: 0 | P12: 0 | Q12: 0 | R12: 108 | T12: 1 | V12: 0 | BB12: 0 | BH12: Сметные нормы списания | BI12: Коды ОКП для СН-2012 - 2024 г. (в ценах на 01.01.2024 г) | BJ12: 1 | BK12: 1 | BL12: 0 | BM12: 0 | BN12: 1 | BO12: 0 | BP12: 6 | BQ12: 2 | BR12: 1 | BS12: 1 | BT12: 1 | BU12: 0 | BV12: 1 | BW12: 0 | BX12: 0 | BY12: СН-2012 - 2024 г. (в ценах на 01.01.2024 г)_глава_1-5 | BZ12: Типовой расчет для СН-2012 - 2024 г. (в ценах на 01.01.2024 г) И0 | CA12: СН-2012-2024 г. База данных "Сборник стоимостных нормативов" (в ценах на 01.01.2024 г) | CB12: СН-2012-2024 г. База данных "Сборник стоимостных нормативов" (в ценах на 01.01.2024 г) | CC12: СН-2012-2024 г. База данных "Сборник стоимостных нормативов" (в ценах на 01.01.2024 г) | CD12: СН-2012-2024 г. База данных "Сборник стоимостных нормативов" (в ценах на 01.01.2024 г) | CE12: Поправки для СН-2012-2024 в ценах на 01.01.2024 г И0 (05.03.2024) | CF12: 0 | CG12: 0 | CH12: 8 | CK12: 0 | CY12: 0 | EC12: 0
A15: 15 | B15: 1
A18: 52 | B18: =B522 -> 581 | C18: =C522 -> 1 | D18: =D522 -> 12 | E18: =E522 -> 0 | F18: =F522 -> Новый объект | G18: =G522 -> +Текущий ремонт спортзала №1 + раздевалки по адресу: г. Москва, ул. Митинская улица, д. 48, корп. 2 | O18: =O522 -> 1626320.4 | P18: =P522 -> 1011274.7 | Q18: =Q522 -> 23758.01 | R18: =R522 -> 18629.83 | S18: =S522 -> 591287.74 | T18: =T522 -> 0 | U18: =U522 -> 1979.8973 | V18: =V522 -> 0 | ... GX18: =GX522 -> 0
A20: 3 | B20: 1 | D20: =ROW(A492) -> 492 | F20: Новая локальная смета | G20: Новая локальная смета | I20: 0 | K20: 0 | S20: 0 | V20: 0 | BX20: 0 | CF20: 0 | CG20: 0
A22: 52 | B22: =B492 -> 1 | C22: =C492 -> 3 | D22: =D492 -> 20 | E22: =E492 -> 0 | F22: =F492 -> Новая локальная смета | G22: =G492 -> Новая локальная смета | O22: =O492 -> 1626320.4 | P22: =P492 -> 1011274.7 | Q22: =Q492 -> 23758.01 | R22: =R492 -> 18629.83 | S22: =S492 -> 591287.74 | T22: =T492 -> 0 | U22: =U492 -> 1979.8973 | V22: =V492 -> 0 | ... GX22: =GX492 -> 0
A24: 4 | B24: 1 | D24: =ROW(A217) -> 217 | F24: Новый раздел | G24: 1. Спортзал №1 | I24: 0 | K24: -1 | S24: 0 | V24: 0 | BX24: 0 | CJ24: 0
A26: 52 | B26: =B217 -> 1 | C26: =C217 -> 4 | D26: =D217 -> 24 | E26: =E217 -> 0 | F26: =F217 -> Новый раздел | G26: =G217 -> 1. Спортзал №1 | O26: =O217 -> 1324696.3 | P26: =P217 -> 823257.85 | Q26: =Q217 -> 18608.83 | R26: =R217 -> 15938.48 | S26: =S217 -> 482829.6 | T26: =T217 -> 0 | U26: =U217 -> 1632.4503 | V26: =V217 -> 0 | ... GX26: =GX217 -> 0
A28: 5 | B28: 1 | D28: =ROW(A43) -> 43 | F28: Новый подраздел | G28: 1.1 Демонтажные работы | I28: 0 | K28: -1 | S28: 0 | V28: 0 | BX28: 0 | CJ28: 0
A30: 52 | B30: =B43 -> 1 | C30: =C43 -> 5 | D30: =D43 -> 28 | E30: =E43 -> 0 | F30: =F43 -> Новый подраздел | G30: =G43 -> 1.1 Демонтажные работы | O30: =O43 -> 84927.54 | P30: =P43 -> 1294.22 | Q30: =Q43 -> 2276.91 | R30: =R43 -> 1683.29 | S30: =S43 -> 81356.41 | T30: =T43 -> 0 | U30: =U43 -> 318.20593 | V30: =V43 -> 0 | ... GX30: =GX43 -> 0
A32: 17 | B32: 1 | D32: =ROW(EtalonRes!A2) -> 2 | E32: 1 | F32: 1.1-3404-4-2/1 | G32: Разборка плинтусов поливинилхлоридных с креплением шурупами | H32: 100 м | I32: 0.6504 | J32: 0 | K32: 0.6504 | O32: =ROUND(CP32,2) -> 456.13 | P32: =ROUND(CQ32*I32,2) -> 0 | Q32: =ROUND(CR32*I32,2) -> 1.16 | R32: =ROUND(CS32*I32,2) -> 0 | S32: =ROUND(CT32*I32,2) -> 454.97 | T32: =ROUND(CU32*I32,2) -> 0 | U32: =CV32*I32 -> 1.808112 | V32: =CW32*I32 -> 0 | W32: =ROUND(CX32*I32,2) -> 0 | X32: =ROUND(CY32,2) -> 318.48 | Y32: =ROUND(CZ32,2) -> 45.5 | AA32: 72192302 | AB32: =ROUND((AC32+AD32+AF32),6) -> 701.32 | AC32: =ROUND((ES32),6) -> 0 | AD32: =ROUND((((ET32)-(EU32))+AE32),6) -> 1.79 | AE32: =ROUND((EU32),6) -> 0 | AF32: =ROUND((EV32),6) -> 699.53 | AG32: =ROUND((AP32),6) -> 0 | AH32: =(EW32) -> 2.78 | AI32: =(EX32) -> 0 | AJ32: =(AS32) -> 0 | AK32: 701.32 | AL32: 0 | AM32: 1.79 | AN32: 0 | AO32: 699.53 | AP32: 0 | AQ32: 2.78 | AR32: 0 | AS32: 0 | AT32: 70 | AU32: 10 | AV32: 1 | AW32: 1 | AZ32: 1 | BA32: 1 | BB32: 1 | BC32: 1 | BH32: 0 | BI32: 4 | BJ32: СН-2012-2024.1. База. Сб.10-3404-4-2/1 | BM32: 0 | BN32: 0 | BP32: 0 | BQ32: 1 | BR32: 0 | BS32: 1 | BT32: 1 | BU32: 1 | BV32: 1 | BW32: 1 | BX32: 1 | BZ32: 70 | CA32: 10 | CE32: 0 | CF32: 0 | CG32: 0 | CM32: 0 | CO32: 0 | CP32: =(P32+Q32+S32) -> 456.13 | CQ32: =(AC32*BC32*AW32) -> 0 | CR32: =((((ET32)*BB32-(EU32)*BS32)+AE32*BS32)*AV32) -> 1.79 | CS32: =(AE32*BS32*AV32) -> 0 | CT32: =(AF32*BA32*AV32) -> 699.53 | CU32: =AG32 -> 0 | CV32: =(AH32*AV32) -> 2.78 | CW32: =AI32 -> 0 | CX32: =AJ32 -> 0 | CY32: =((S32*BZ32)/100) -> 318.479 | CZ32: =((S32*CA32)/100) -> 45.497 | DN32: 0 | DO32: 0 | DP32: 1 | DQ32: 1 | DU32: 1003 | DV32: 100 м | DW32: 100 м | DX32: 100 | EE32: 71753531 | EF32: 1 | EG32: СН-2012 | EH32: 0 | EJ32: 4 | EK32: 0 | EL32: Подрядные работы, гл. 1-5,7 | EM32: работа | EQ32: 0 | ER32: 701.32 | ES32: 0 | ET32: 1.79 | EU32: 0 | EV32: 699.53 | EW32: 2.78 | EX32: 0 | EY32: 0 | FQ32: 0 | FR32: =ROUND(IF(BI32=3,GM32,0),2) -> 0 | FS32: 0 | FX32: 70 | FY32: 10 | GD32: 0 | GF32: -1249124778 | GG32: 2 | GH32: 1 | GI32: -2 | GJ32: 0 | GK32: =ROUND(R32*(R12)/100,2) -> 0 | GL32: =ROUND(IF(AND(BH32=3,BI32=3,FS32<>0),P32,0),2) -> 0 | GM32: =ROUND(O32+X32+Y32+GK32,2)+GX32 -> 820.11 | GN32: =IF(OR(BI32=0,BI32=1),GM32,0) -> 0 | GO32: =IF(BI32=2,GM32,0) -> 0 | GP32: =IF(BI32=4,GM32+GX32,0) -> 820.11 | GR32: 0 | GS32: 3 | GT32: 0 | GV32: =ROUND((GT32),6) -> 0 | GW32: 1 | GX32: =ROUND(HC32*I32,2) -> 0 | HA32: 0 | HB32: 0 | HC32: =GV32*GW32 -> 0 | IK32: 0
A33: 17 | B33: 1 | D33: =ROW(EtalonRes!A3) -> 3 | E33: 2 | F33: 1.3-3204-1-1/1 | G33: Расчистка поверхностей от старых покрасок (шпателем, щетками и т.д.) | H33: м2 | I33: =ROUND(283.2+118.77,9) -> 401.97 | J33: 0 | K33: =ROUND(283.2+118.77,9) -> 401.97 | O33: =ROUND(CP33,2) -> 59797.06 | P33: =ROUND(CQ33*I33,2) -> 0 | Q33: =ROUND(CR33*I33,2) -> 0 | R33: =ROUND(CS33*I33,2) -> 0 | S33: =ROUND(CT33*I33,2) -> 59797.06 | T33: =ROUND(CU33*I33,2) -> 0 | U33: =CV33*I33 -> 241.182 | V33: =CW33*I33 -> 0 | W33: =ROUND(CX33*I33,2) -> 0 | X33: =ROUND(CY33,2) -> 41857.94 | Y33: =ROUND(CZ33,2) -> 5979.71 | AA33: 72192302 | AB33: =ROUND((AC33+AD33+AF33),6) -> 148.76 | AC33: =ROUND((ES33),6) -> 0 | AD33: =ROUND((((ET33)-(EU33))+AE33),6) -> 0 | AE33: =ROUND((EU33),6) -> 0 | AF33: =ROUND((EV33),6) -> 148.76 | AG33: =ROUND((AP33),6) -> 0 | AH33: =(EW33) -> 0.6 | AI33: =(EX33) -> 0 | AJ33: =(AS33) -> 0 | AK33: 148.76 | AL33: 0 | AM33: 0 | AN33: 0 | AO33: 148.76 | AP33: 0 | AQ33: 0.6 | AR33: 0 | AS33: 0 | AT33: 70 | AU33: 10 | AV33: 1 | AW33: 1 | AZ33: 1 | BA33: 1 | BB33: 1 | BC33: 1 | BH33: 0 | BI33: 4 | BJ33: СН-2012-2024.1. База. Сб.13-3204-1-1/1 | BM33: 0 | BN33: 0 | BP33: 0 | BQ33: 1 | BR33: 0 | BS33: 1 | BT33: 1 | BU33: 1 | BV33: 1 | BW33: 1 | BX33: 1 | BZ33: 70 | CA33: 10 | CE33: 0 | CF33: 0 | CG33: 0 | CM33: 0 | CO33: 0 | CP33: =(P33+Q33+S33) -> 59797.06 | CQ33: =(AC33*BC33*AW33) -> 0 | CR33: =((((ET33)*BB33-(EU33)*BS33)+AE33*BS33)*AV33) -> 0 | CS33: =(AE33*BS33*AV33) -> 0 | CT33: =(AF33*BA33*AV33) -> 148.76 | CU33: =AG33 -> 0 | CV33: =(AH33*AV33) -> 0.6 | CW33: =AI33 -> 0 | CX33: =AJ33 -> 0 | CY33: =((S33*BZ33)/100) -> 41857.942 | CZ33: =((S33*CA33)/100) -> 5979.706 | DN33: 0 | DO33: 0 | DP33: 1 | DQ33: 1 | DU33: 1005 | DV33: м2 | DW33: м2 | DX33: 1 | EE33: 71753531 | EF33: 1 | EG33: СН-2012 | EH33: 0 | EJ33: 4 | EK33: 0 | EL33: Подрядные работы, гл. 1-5,7 | EM33: работа | EQ33: 0 | ER33: 148.76 | ES33: 0 | ET33: 0 | EU33: 0 | EV33: 148.76 | EW33: 0.6 | EX33: 0 | EY33: 0 | FQ33: 0 | FR33: =ROUND(IF(BI33=3,GM33,0),2) -> 0 | FS33: 0 | FX33: 70 | FY33: 10 | GD33: 0 | GF33: -1536673318 | GG33: 2 | GH33: 1 | GI33: -2 | GJ33: 0 | GK33: =ROUND(R33*(R12)/100,2) -> 0 | GL33: =ROUND(IF(AND(BH33=3,BI33=3,FS33<>0),P33,0),2) -> 0 | GM33: =ROUND(O33+X33+Y33+GK33,2)+GX33 -> 107634.71 | GN33: =IF(OR(BI33=0,BI33=1),GM33,0) -> 0 | GO33: =IF(BI33=2,GM33,0) -> 0 | GP33: =IF(BI33=4,GM33+GX33,0) -> 107634.71 | GR33: 0 | GS33: 3 | GT33: 0 | GV33: =ROUND((GT33),6) -> 0 | GW33: 1 | GX33: =ROUND(HC33*I33,2) -> 0 | HA33: 0 | HB33: 0 | HC33: =GV33*GW33 -> 0 | IK33: 0
A34: 17 | B34: 1 | D34: =ROW(EtalonRes!A5) -> 5 | E34: 3 | F34: 1.1-3304-1-1/1 | G34: Демонтаж радиатора массой до 80 кг | H34: 100 шт. | I34: 0.26 | J34: 0 | K34: 0.26 | O34: =ROUND(CP34,2) -> 8234.34 | P34: =ROUND(CQ34*I34,2) -> 0 | Q34: =ROUND(CR34*I34,2) -> 0 | R34: =ROUND(CS34*I34,2) -> 0 | S34: =ROUND(CT34*I34,2) -> 8234.34 | T34: =ROUND(CU34*I34,2) -> 0 | U34: =CV34*I34 -> 31.3534 | V34: =CW34*I34 -> 0 | W34: =ROUND(CX34*I34,2) -> 0 | X34: =ROUND(CY34,2) -> 5764.04 | Y34: =ROUND(CZ34,2) -> 823.43 | AA34: 72192302 | AB34: =ROUND((AC34+AD34+AF34),6) -> 31670.55 | AC34: =ROUND((ES34),6) -> 0 | AD34: =ROUND((((ET34)-(EU34))+AE34),6) -> 0 | AE34: =ROUND((EU34),6) -> 0 | AF34: =ROUND((EV34),6) -> 31670.55 | AG34: =ROUND((AP34),6) -> 0 | AH34: =(EW34) -> 120.59 | AI34: =(EX34) -> 0 | AJ34: =(AS34) -> 0 | AK34: 31670.55 | AL34: 0 | AM34: 0 | AN34: 0 | AO34: 31670.55 | AP34: 0 | AQ34: 120.59 | AR34: 0 | AS34: 0 | AT34: 70 | AU34: 10 | AV34: 1 | AW34: 1 | AZ34: 1 | BA34: 1 | BB34: 1 | BC34: 1 | BH34: 0 | BI34: 4 | BJ34: СН-2012-2024.1. База. Сб.17-3304-1-1/1 | BM34: 0 | BN34: 0 | BP34: 0 | BQ34: 1 | BR34: 0 | BS34: 1 | BT34: 1 | BU34: 1 | BV34: 1 | BW34: 1 | BX34: 1 | BZ34: 70 | CA34: 10 | CE34: 0 | CF34: 0 | CG34: 0 | CM34: 0 | CO34: 0 | CP34: =(P34+Q34+S34) -> 8234.34 | CQ34: =(AC34*BC34*AW34) -> 0 | CR34: =((((ET34)*BB34-(EU34)*BS34)+AE34*BS34)*AV34) -> 0 | CS34: =(AE34*BS34*AV34) -> 0 | CT34: =(AF34*BA34*AV34) -> 31670.55 | CU34: =AG34 -> 0 | CV34: =(AH34*AV34) -> 120.59 | CW34: =AI34 -> 0 | CX34: =AJ34 -> 0 | CY34: =((S34*BZ34)/100) -> 5764.038 | CZ34: =((S34*CA34)/100) -> 823.434 | DN34: 0 | DO34: 0 | DP34: 1 | DQ34: 1 | DU34: 1010 | DV34: 100 шт. | DW34: 100 шт. | DX34: 100 | EE34: 71753531 | EF34: 1 | EG34: СН-2012 | EH34: 0 | EJ34: 4 | EK34: 0 | EL34: Подрядные работы, гл. 1-5,7 | EM34: работа | EQ34: 0 | ER34: 31670.55 | ES34: 0 | ET34: 0 | EU34: 0 | EV34: 31670.55 | EW34: 120.59 | EX34: 0 | EY34: 0 | FQ34: 0 | FR34: =ROUND(IF(BI34=3,GM34,0),2) -> 0 | FS34: 0 | FX34: 70 | FY34: 10 | GD34: 0 | GF34: 1879916655 | GG34: 2 | GH34: 1 | GI34: -2 | GJ34: 0 | GK34: =ROUND(R34*(R12)/100,2) -> 0 | GL34: =ROUND(IF(AND(BH34=3,BI34=3,FS34<>0),P34,0),2) -> 0 | GM34: =ROUND(O34+X34+Y34+GK34,2)+GX34 -> 14821.81 | GN34: =IF(OR(BI34=0,BI34=1),GM34,0) -> 0 | GO34: =IF(BI34=2,GM34,0) -> 0 | GP34: =IF(BI34=4,GM34+GX34,0) -> 14821.81 | GR34: 0 | GS34: 3 | GT34: 0 | GV34: =ROUND((GT34),6) -> 0 | GW34: 1 | GX34: =ROUND(HC34*I34,2) -> 0 | HA34: 0 | HB34: 0 | HC34: =GV34*GW34 -> 0 | IK34: 0
A35: 18 | B35: 1 | E35: 4 | F35: 9999990001 | G35: Масса мусора | H35: т | I35: =I34*J35 -> -2.08 | J35: -8 | K35: -8 | O35: =ROUND(CP35,2) -> 0 | P35: =ROUND(CQ35*I35,2) -> 0 | Q35: =ROUND(CR35*I35,2) -> 0 | R35: =ROUND(CS35*I35,2) -> 0 | S35: =ROUND(CT35*I35,2) -> 0 | T35: =ROUND(CU35*I35,2) -> 0 | U35: =CV35*I35 -> 0 | V35: =CW35*I35 -> 0 | W35: =ROUND(CX35*I35,2) -> 0 | X35: =ROUND(CY35,2) -> 0 | Y35: =ROUND(CZ35,2) -> 0 | AA35: 72192302 | AB35: =ROUND((AC35+AD35+AF35),6) -> 0 | AC35: =ROUND((ES35),6) -> 0 | AD35: =ROUND((((ET35)-(EU35))+AE35),6) -> 0 | AE35: =ROUND((EU35),6) -> 0 | AF35: =ROUND((EV35),6) -> 0 | AG35: =ROUND((AP35),6) -> 0 | AH35: =(EW35) -> 0 | AI35: =(EX35) -> 0 | AJ35: =(AS35) -> 0 | AK35: 0 | AL35: 0 | AM35: 0 | AN35: 0 | AO35: 0 | AP35: 0 | AQ35: 0 | AR35: 0 | AS35: 0 | AT35: 70 | AU35: 10 | AV35: 1 | AW35: 1 | AZ35: 1 | BA35: 1 | BB35: 1 | BC35: 1 | BH35: 3 | BI35: 4 | BM35: 0 | BN35: 0 | BP35: 0 | BQ35: 1 | BR35: 1 | BS35: 1 | BT35: 1 | BU35: 1 | BV35: 1 | BW35: 1 | BX35: 1 | BZ35: 70 | CA35: 10 | CE35: 0 | CF35: 0 | CG35: 0 | CM35: 0 | CO35: 0 | CP35: =(P35+Q35+S35) -> 0 | CQ35: =(AC35*BC35*AW35) -> 0 | CR35: =((((ET35)*BB35-(EU35)*BS35)+AE35*BS35)*AV35) -> 0 | CS35: =(AE35*BS35*AV35) -> 0 | CT35: =(AF35*BA35*AV35) -> 0 | CU35: =AG35 -> 0 | CV35: =(AH35*AV35) -> 0 | CW35: =AI35 -> 0 | CX35: =AJ35 -> 0 | CY35: =((S35*BZ35)/100) -> 0 | CZ35: =((S35*CA35)/100) -> 0 | DN35: 0 | DO35: 0 | DP35: 1 | DQ35: 1 | DU35: 1009 | DV35: т | DW35: т | DX35: 1000 | EE35: 71753531 | EF35: 1 | EG35: СН-2012 | EH35: 0 | EJ35: 4 | EK35: 0 | EL35: Подрядные работы, гл. 1-5,7 | EM35: работа | EQ35: 0 | ER35: 0 | ES35: 0 | ET35: 0 | EU35: 0 | EV35: 0 | EW35: 0 | EX35: 0 | FQ35: 0 | FR35: =ROUND(IF(BI35=3,GM35,0),2) -> 0 | FS35: 0 | FX35: 70 | FY35: 10 | GD35: 0 | GF35: 1489638031 | GG35: 2 | GH35: 1 | GI35: -2 | GJ35: 0 | GK35: =ROUND(R35*(R12)/100,2) -> 0 | GL35: =ROUND(IF(AND(BH35=3,BI35=3,FS35<>0),P35,0),2) -> 0 | GM35: =ROUND(O35+X35+Y35+GK35,2)+GX35 -> 0 | GN35: =IF(OR(BI35=0,BI35=1),GM35,0) -> 0 | GO35: =IF(BI35=2,GM35,0) -> 0 | GP35: =IF(BI35=4,GM35+GX35,0) -> 0 | GR35: 0 | GS35: 3 | GT35: 0 | GV35: =ROUND((GT35),6) -> 0 | GW35: 1 | GX35: =ROUND(HC35*I35,2) -> 0 | HA35: 0 | HB35: 0 | HC35: =GV35*GW35 -> 0 | IK35: 0
A36: 17 | B36: 1 | D36: =ROW(EtalonRes!A8) -> 8 | E36: 5 | F36: 1.50-3203-34-1/1 | G36: Устройство и разборка защитного ограждения лесов из сетки | H36: 100 м2 | I36: 0.776 | J36: 0 | K36: 0.776 | O36: =ROUND(CP36,2) -> 4128.61 | P36: =ROUND(CQ36*I36,2) -> 1078.43 | Q36: =ROUND(CR36*I36,2) -> 0 | R36: =ROUND(CS36*I36,2) -> 0 | S36: =ROUND(CT36*I36,2) -> 3050.18 | T36: =ROUND(CU36*I36,2) -> 0 | U36: =CV36*I36 -> 9.90952 | V36: =CW36*I36 -> 0 | W36: =ROUND(CX36*I36,2) -> 0 | X36: =ROUND(CY36,2) -> 2135.13 | Y36: =ROUND(CZ36,2) -> 305.02 | AA36: 72192302 | AB36: =ROUND((AC36+AD36+AF36),6) -> 5320.38 | AC36: =ROUND((ES36),6) -> 1389.73 | AD36: =ROUND((((ET36)-(EU36))+AE36),6) -> 0 | AE36: =ROUND((EU36),6) -> 0 | AF36: =ROUND((EV36),6) -> 3930.65 | AG36: =ROUND((AP36),6) -> 0 | AH36: =(EW36) -> 12.77 | AI36: =(EX36) -> 0 | AJ36: =(AS36) -> 0 | AK36: 5320.38 | AL36: 1389.73 | AM36: 0 | AN36: 0 | AO36: 3930.65 | AP36: 0 | AQ36: 12.77 | AR36: 0 | AS36: 0 | AT36: 70 | AU36: 10 | AV36: 1 | AW36: 1 | AZ36: 1 | BA36: 1 | BB36: 1 | BC36: 1 | BH36: 0 | BI36: 4 | BJ36: СН-2012-2024.1. База. Сб.50-3203-34-1/1 | BM36: 0 | BN36: 0 | BP36: 0 | BQ36: 1 | BR36: 0 | BS36: 1 | BT36: 1 | BU36: 1 | BV36: 1 | BW36: 1 | BX36: 1 | BZ36: 70 | CA36: 10 | CE36: 0 | CF36: 0 | CG36: 0 | CM36: 0 | CO36: 0 | CP36: =(P36+Q36+S36) -> 4128.61 | CQ36: =(AC36*BC36*AW36) -> 1389.73 | CR36: =((((ET36)*BB36-(EU36)*BS36)+AE36*BS36)*AV36) -> 0 | CS36: =(AE36*BS36*AV36) -> 0 | CT36: =(AF36*BA36*AV36) -> 3930.65 | CU36: =AG36 -> 0 | CV36: =(AH36*AV36) -> 12.77 | CW36: =AI36 -> 0 | CX36: =AJ36 -> 0 | CY36: =((S36*BZ36)/100) -> 2135.126 | CZ36: =((S36*CA36)/100) -> 305.018 | DN36: 0 | DO36: 0 | DP36: 1 | DQ36: 1 | DU36: 1005 | DV36: 100 м2 | DW36: 100 м2 | DX36: 100 | EE36: 71753531 | EF36: 1 | EG36: СН-2012 | EH36: 0 | EJ36: 4 | EK36: 0 | EL36: Подрядные работы, гл. 1-5,7 | EM36: работа | EQ36: 0 | ER36: 5320.38 | ES36: 1389.73 | ET36: 0 | EU36: 0 | EV36: 3930.65 | EW36: 12.77 | EX36: 0 | EY36: 0 | FQ36: 0 | FR36: =ROUND(IF(BI36=3,GM36,0),2) -> 0 | FS36: 0 | FX36: 70 | FY36: 10 | GD36: 0 | GF36: 550753279 | GG36: 2 | GH36: 1 | GI36: -2 | GJ36: 0 | GK36: =ROUND(R36*(R12)/100,2) -> 0 | GL36: =ROUND(IF(AND(BH36=3,BI36=3,FS36<>0),P36,0),2) -> 0 | GM36: =ROUND(O36+X36+Y36+GK36,2)+GX36 -> 6568.76 | GN36: =IF(OR(BI36=0,BI36=1),GM36,0) -> 0 | GO36: =IF(BI36=2,GM36,0) -> 0 | GP36: =IF(BI36=4,GM36+GX36,0) -> 6568.76 | GR36: 0 | GS36: 3 | GT36: 0 | GV36: =ROUND((GT36),6) -> 0 | GW36: 1 | GX36: =ROUND(HC36*I36,2) -> 0 | HA36: 0 | HB36: 0 | HC36: =GV36*GW36 -> 0 | IK36: 0
A37: 17 | B37: 1 | D37: =ROW(EtalonRes!A13) -> 13 | E37: 6 | F37: 1.7-3204-1-4/1 | G37: Разборка трубопроводов центрального отопления на сварке диаметром труб до 50 мм | H37: 100 м | I37: 0.4 | J37: 0 | K37: 0.4 | O37: =ROUND(CP37,2) -> 5584.83 | P37: =ROUND(CQ37*I37,2) -> 215.79 | Q37: =ROUND(CR37*I37,2) -> 11.9 | R37: =ROUND(CS37*I37,2) -> 0.34 | S37: =ROUND(CT37*I37,2) -> 5357.14 | T37: =ROUND(CU37*I37,2) -> 0 | U37: =CV37*I37 -> 19.736 | V37: =CW37*I37 -> 0 | W37: =ROUND(CX37*I37,2) -> 0 | X37: =ROUND(CY37,2) -> 3750 | Y37: =ROUND(CZ37,2) -> 535.71 | AA37: 72192302 | AB37: =ROUND((AC37+AD37+AF37),6) -> 13962.07 | AC37: =ROUND((ES37),6) -> 539.47 | AD37: =ROUND((((ET37)-(EU37))+AE37),6) -> 29.75 | AE37: =ROUND((EU37),6) -> 0.85 | AF37: =ROUND((EV37),6) -> 13392.85 | AG37: =ROUND((AP37),6) -> 0 | AH37: =(EW37) -> 49.34 | AI37: =(EX37) -> 0 | AJ37: =(AS37) -> 0 | AK37: 13962.07 | AL37: 539.47 | AM37: 29.75 | AN37: 0.85 | AO37: 13392.85 | AP37: 0 | AQ37: 49.34 | AR37: 0 | AS37: 0 | AT37: 70 | AU37: 10 | AV37: 1 | AW37: 1 | AZ37: 1 | BA37: 1 | BB37: 1 | BC37: 1 | BH37: 0 | BI37: 4 | BJ37: СН-2012-2024.1. База. Сб.17-3204-1-4/1 | BM37: 0 | BN37: 0 | BP37: 0 | BQ37: 1 | BR37: 0 | BS37: 1 | BT37: 1 | BU37: 1 | BV37: 1 | BW37: 1 | BX37: 1 | BZ37: 70 | CA37: 10 | CE37: 0 | CF37: 0 | CG37: 0 | CM37: 0 | CO37: 0 | CP37: =(P37+Q37+S37) -> 5584.83 | CQ37: =(AC37*BC37*AW37) -> 539.47 | CR37: =((((ET37)*BB37-(EU37)*BS37)+AE37*BS37)*AV37) -> 29.75 | CS37: =(AE37*BS37*AV37) -> 0.85 | CT37: =(AF37*BA37*AV37) -> 13392.85 | CU37: =AG37 -> 0 | CV37: =(AH37*AV37) -> 49.34 | CW37: =AI37 -> 0 | CX37: =AJ37 -> 0 | CY37: =((S37*BZ37)/100) -> 3749.998 | CZ37: =((S37*CA37)/100) -> 535.714 | DN37: 0 | DO37: 0 | DP37: 1 | DQ37: 1 | DU37: 1003 | DV37: 100 м | DW37: 100 м | DX37: 100 | EE37: 71753531 | EF37: 1 | EG37: СН-2012 | EH37: 0 | EJ37: 4 | EK37: 0 | EL37: Подрядные работы, гл. 1-5,7 | EM37: работа | EQ37: 0 | ER37: 13962.07 | ES37: 539.47 | ET37: 29.75 | EU37: 0.85 | EV37: 13392.85 | EW37: 49.34 | EX37: 0 | EY37: 0 | FQ37: 0 | FR37: =ROUND(IF(BI37=3,GM37,0),2) -> 0 | FS37: 0 | FX37: 70 | FY37: 10 | GD37: 0 | GF37: 393771794 | GG37: 2 | GH37: 1 | GI37: -2 | GJ37: 0 | GK37: =ROUND(R37*(R12)/100,2) -> 0.37 | GL37: =ROUND(IF(AND(BH37=3,BI37=3,FS37<>0),P37,0),2) -> 0 | GM37: =ROUND(O37+X37+Y37+GK37,2)+GX37 -> 9870.91 | GN37: =IF(OR(BI37=0,BI37=1),GM37,0) -> 0 | GO37: =IF(BI37=2,GM37,0) -> 0 | GP37: =IF(BI37=4,GM37+GX37,0) -> 9870.91 | GR37: 0 | GS37: 3 | GT37: 0 | GV37: =ROUND((GT37),6) -> 0 | GW37: 1 | GX37: =ROUND(HC37*I37,2) -> 0 | HA37: 0 | HB37: 0 | HC37: =GV37*GW37 -> 0 | IK37: 0
A38: 18 | B38: 1 | E38: 7 | F38: 9999990001 | G38: Масса мусора | H38: т | I38: =I37*J38 -> -0.1816 | J38: -0.454 | K38: -0.454 | O38: =ROUND(CP38,2) -> 0 | P38: =ROUND(CQ38*I38,2) -> 0 | Q38: =ROUND(CR38*I38,2) -> 0 | R38: =ROUND(CS38*I38,2) -> 0 | S38: =ROUND(CT38*I38,2) -> 0 | T38: =ROUND(CU38*I38,2) -> 0 | U38: =CV38*I38 -> 0 | V38: =CW38*I38 -> 0 | W38: =ROUND(CX38*I38,2) -> 0 | X38: =ROUND(CY38,2) -> 0 | Y38: =ROUND(CZ38,2) -> 0 | AA38: 72192302 | AB38: =ROUND((AC38+AD38+AF38),6) -> 0 | AC38: =ROUND((ES38),6) -> 0 | AD38: =ROUND((((ET38)-(EU38))+AE38),6) -> 0 | AE38: =ROUND((EU38),6) -> 0 | AF38: =ROUND((EV38),6) -> 0 | AG38: =ROUND((AP38),6) -> 0 | AH38: =(EW38) -> 0 | AI38: =(EX38) -> 0 | AJ38: =(AS38) -> 0 | AK38: 0 | AL38: 0 | AM38: 0 | AN38: 0 | AO38: 0 | AP38: 0 | AQ38: 0 | AR38: 0 | AS38: 0 | AT38: 70 | AU38: 10 | AV38: 1 | AW38: 1 | AZ38: 1 | BA38: 1 | BB38: 1 | BC38: 1 | BH38: 3 | BI38: 4 | BM38: 0 | BN38: 0 | BP38: 0 | BQ38: 1 | BR38: 1 | BS38: 1 | BT38: 1 | BU38: 1 | BV38: 1 | BW38: 1 | BX38: 1 | BZ38: 70 | CA38: 10 | CE38: 0 | CF38: 0 | CG38: 0 | CM38: 0 | CO38: 0 | CP38: =(P38+Q38+S38) -> 0 | CQ38: =(AC38*BC38*AW38) -> 0 | CR38: =((((ET38)*BB38-(EU38)*BS38)+AE38*BS38)*AV38) -> 0 | CS38: =(AE38*BS38*AV38) -> 0 | CT38: =(AF38*BA38*AV38) -> 0 | CU38: =AG38 -> 0 | CV38: =(AH38*AV38) -> 0 | CW38: =AI38 -> 0 | CX38: =AJ38 -> 0 | CY38: =((S38*BZ38)/100) -> 0 | CZ38: =((S38*CA38)/100) -> 0 | DN38: 0 | DO38: 0 | DP38: 1 | DQ38: 1 | DU38: 1009 | DV38: т | DW38: т | DX38: 1000 | EE38: 71753531 | EF38: 1 | EG38: СН-2012 | EH38: 0 | EJ38: 4 | EK38: 0 | EL38: Подрядные работы, гл. 1-5,7 | EM38: работа | EQ38: 0 | ER38: 0 | ES38: 0 | ET38: 0 | EU38: 0 | EV38: 0 | EW38: 0 | EX38: 0 | FQ38: 0 | FR38: =ROUND(IF(BI38=3,GM38,0),2) -> 0 | FS38: 0 | FX38: 70 | FY38: 10 | GD38: 0 | GF38: 1489638031 | GG38: 2 | GH38: 1 | GI38: -2 | GJ38: 0 | GK38: =ROUND(R38*(R12)/100,2) -> 0 | GL38: =ROUND(IF(AND(BH38=3,BI38=3,FS38<>0),P38,0),2) -> 0 | GM38: =ROUND(O38+X38+Y38+GK38,2)+GX38 -> 0 | GN38: =IF(OR(BI38=0,BI38=1),GM38,0) -> 0 | GO38: =IF(BI38=2,GM38,0) -> 0 | GP38: =IF(BI38=4,GM38+GX38,0) -> 0 | GR38: 0 | GS38: 3 | GT38: 0 | GV38: =ROUND((GT38),6) -> 0 | GW38: 1 | GX38: =ROUND(HC38*I38,2) -> 0 | HA38: 0 | HB38: 0 | HC38: =GV38*GW38 -> 0 | IK38: 0
A39: 17 | B39: 1 | D39: =ROW(EtalonRes!A14) -> 14 | E39: 8 | F39: 1.2-3105-1-1/1 | G39: Вынос и занос мебели, в том числе спортивных снарядов массой до 50 кг | H39: шт. | I39: 15 | J39: 0 | K39: 15 | O39: =ROUND(CP39,2) -> 706.65 | P39: =ROUND(CQ39*I39,2) -> 0 | Q39: =ROUND(CR39*I39,2) -> 0 | R39: =ROUND(CS39*I39,2) -> 0 | S39: =ROUND(CT39*I39,2) -> 706.65 | T39: =ROUND(CU39*I39,2) -> 0 | U39: =CV39*I39 -> 2.85 | V39: =CW39*I39 -> 0 | W39: =ROUND(CX39*I39,2) -> 0 | X39: =ROUND(CY39,2) -> 494.66 | Y39: =ROUND(CZ39,2) -> 70.67 | AA39: 72192302 | AB39: =ROUND((AC39+AD39+AF39),6) -> 47.11 | AC39: =ROUND((ES39),6) -> 0 | AD39: =ROUND((((ET39)-(EU39))+AE39),6) -> 0 | AE39: =ROUND((EU39),6) -> 0 | AF39: =ROUND((EV39),6) -> 47.11 | AG39: =ROUND((AP39),6) -> 0 | AH39: =(EW39) -> 0.19 | AI39: =(EX39) -> 0 | AJ39: =(AS39) -> 0 | AK39: 47.11 | AL39: 0 | AM39: 0 | AN39: 0 | AO39: 47.11 | AP39: 0 | AQ39: 0.19 | AR39: 0 | AS39: 0 | AT39: 70 | AU39: 10 | AV39: 1 | AW39: 1 | AZ39: 1 | BA39: 1 | BB39: 1 | BC39: 1 | BH39: 0 | BI39: 4 | BJ39: СН-2012-2024.1. База. Сб.26-3105-1-1/1 | BM39: 0 | BN39: 0 | BP39: 0 | BQ39: 1 | BR39: 0 | BS39: 1 | BT39: 1 | BU39: 1 | BV39: 1 | BW39: 1 | BX39: 1 | BZ39: 70 | CA39: 10 | CE39: 0 | CF39: 0 | CG39: 0 | CM39: 0 | CO39: 0 | CP39: =(P39+Q39+S39) -> 706.65 | CQ39: =(AC39*BC39*AW39) -> 0 | CR39: =((((ET39)*BB39-(EU39)*BS39)+AE39*BS39)*AV39) -> 0 | CS39: =(AE39*BS39*AV39) -> 0 | CT39: =(AF39*BA39*AV39) -> 47.11 | CU39: =AG39 -> 0 | CV39: =(AH39*AV39) -> 0.19 | CW39: =AI39 -> 0 | CX39: =AJ39 -> 0 | CY39: =((S39*BZ39)/100) -> 494.655 | CZ39: =((S39*CA39)/100) -> 70.665 | DN39: 0 | DO39: 0 | DP39: 1 | DQ39: 1 | DU39: 1010 | DV39: шт. | DW39: шт. | DX39: 1 | EE39: 71753531 | EF39: 1 | EG39: СН-2012 | EH39: 0 | EJ39: 4 | EK39: 0 | EL39: Подрядные работы, гл. 1-5,7 | EM39: работа | EQ39: 0 | ER39: 47.11 | ES39: 0 | ET39: 0 | EU39: 0 | EV39: 47.11 | EW39: 0.19 | EX39: 0 | EY39: 0 | FQ39: 0 | FR39: =ROUND(IF(BI39=3,GM39,0),2) -> 0 | FS39: 0 | FX39: 70 | FY39: 10 | GD39: 0 | GF39: -873001244 | GG39: 2 | GH39: 1 | GI39: -2 | GJ39: 0 | GK39: =ROUND(R39*(R12)/100,2) -> 0 | GL39: =ROUND(IF(AND(BH39=3,BI39=3,FS39<>0),P39,0),2) -> 0 | GM39: =ROUND(O39+X39+Y39+GK39,2)+GX39 -> 1271.98 | GN39: =IF(OR(BI39=0,BI39=1),GM39,0) -> 0 | GO39: =IF(BI39=2,GM39,0) -> 0 | GP39: =IF(BI39=4,GM39+GX39,0) -> 1271.98 | GR39: 0 | GS39: 3 | GT39: 0 | GV39: =ROUND((GT39),6) -> 0 | GW39: 1 | GX39: =ROUND(HC39*I39,2) -> 0 | HA39: 0 | HB39: 0 | HC39: =GV39*GW39 -> 0 | IK39: 0
A40: 17 | B40: 1 | D40: =ROW(EtalonRes!A19) -> 19 | E40: 9 | F40: 1.50-3203-37-1/1 | G40: Монтаж мелких конструкций из стали различного профиля массой до 20 кг | H40: т | I40: 0.13744 | J40: 0 | K40: 0.13744 | O40: =ROUND(CP40,2) -> 1320.57 | P40: =ROUND(CQ40*I40,2) -> 0 | Q40: =ROUND(CR40*I40,2) -> 26.19 | R40: =ROUND(CS40*I40,2) -> 1.34 | S40: =ROUND(CT40*I40,2) -> 1294.38 | T40: =ROUND(CU40*I40,2) -> 0 | U40: =CV40*I40 -> 3.6668992 | V40: =CW40*I40 -> 0 | W40: =ROUND(CX40*I40,2) -> 0 | X40: =ROUND(CY40,2) -> 906.07 | Y40: =ROUND(CZ40,2) -> 129.44 | AA40: 72192302 | AB40: =ROUND((AC40+AD40+AF40),6) -> 9608.36 | AC40: =ROUND(((ES40*0)),6) -> 0 | AD40: =ROUND(((((ET40*0.2))-((EU40*0.2)))+AE40),6) -> 190.588 | AE40: =ROUND(((EU40*0.2)),6) -> 9.744 | AF40: =ROUND(((EV40*0.2)),6) -> 9417.772 | AG40: =ROUND((AP40),6) -> 0 | AH40: =((EW40*0.2)) -> 26.68 | AI40: =((EX40*0.2)) -> 0 | AJ40: =(AS40) -> 0 | AK40: 188846.85 | AL40: 140805.05 | AM40: 952.94 | AN40: 48.72 | AO40: 47088.86 | AP40: 0 | AQ40: 133.4 | AR40: 0 | AS40: 0 | AT40: 70 | AU40: 10 | AV40: 1 | AW40: 1 | AZ40: 1 | BA40: 1 | BB40: 1 | BC40: 1 | BH40: 0 | BI40: 4 | BJ40: СН-2012-2024.1. База. Сб.50-3203-37-1/1 | BM40: 0 | BN40: 0 | BP40: 0 | BQ40: 1 | BR40: 0 | BS40: 1 | BT40: 1 | BU40: 1 | BV40: 1 | BW40: 1 | BX40: 1 | BZ40: 70 | CA40: 10 | CE40: 0 | CF40: 0 | CG40: 0 | CM40: 0 | CN40: Поправка: СН-2012 О.П. п.22 Наименование: Демонтаж, разборка отдельных бетонных, железобетонных, металлических, деревянных, пластмассовых конструктивных элементов зданий и сооружений, внутренних и наружных инженерных систем и коммуникаций при отсутствии необходимых стоимостных нормативов в сборниках СН-2012 | CO40: 0 | CP40: =(P40+Q40+S40) -> 1320.57 | CQ40: =(AC40*BC40*AW40) -> 0 | CR40: =(((((ET40*0.2))*BB40-((EU40*0.2))*BS40)+AE40*BS40)*AV40) -> 190.588 | CS40: =(AE40*BS40*AV40) -> 9.744 | CT40: =(AF40*BA40*AV40) -> 9417.772 | CU40: =AG40 -> 0 | CV40: =(AH40*AV40) -> 26.68 | CW40: =AI40 -> 0 | CX40: =AJ40 -> 0 | CY40: =((S40*BZ40)/100) -> 906.066 | CZ40: =((S40*CA40)/100) -> 129.438 | DD40: )*0 | DE40: )*0,2 | DF40: )*0,2 | DG40: )*0,2 | DI40: )*0,2 | DJ40: )*0,2 | DN40: 0 | DO40: 0 | DP40: 1 | DQ40: 1 | DU40: 1009 | DV40: т | DW40: т | DX40: 1000 | EE40: 71753531 | EF40: 1 | EG40: СН-2012 | EH40: 0 | EJ40: 4 | EK40: 0 | EL40: Подрядные работы, гл. 1-5,7 | EM40: работа | EO40: Поправка: СН-2012 О.П. п.22 | EQ40: 0 | ER40: 188846.85 | ES40: 140805.05 | ET40: 952.94 | EU40: 48.72 | EV40: 47088.86 | EW40: 133.4 | EX40: 0 | EY40: 0 | FQ40: 0 | FR40: =ROUND(IF(BI40=3,GM40,0),2) -> 0 | FS40: 0 | FX40: 70 | FY40: 10 | GD40: 0 | GF40: 606636601 | GG40: 2 | GH40: 1 | GI40: -2 | GJ40: 0 | GK40: =ROUND(R40*(R12)/100,2) -> 1.45 | GL40: =ROUND(IF(AND(BH40=3,BI40=3,FS40<>0),P40,0),2) -> 0 | GM40: =ROUND(O40+X40+Y40+GK40,2)+GX40 -> 2357.53 | GN40: =IF(OR(BI40=0,BI40=1),GM40,0) -> 0 | GO40: =IF(BI40=2,GM40,0) -> 0 | GP40: =IF(BI40=4,GM40+GX40,0) -> 2357.53 | GR40: 0 | GS40: 3 | GT40: 0 | GV40: =ROUND((GT40),6) -> 0 | GW40: 1 | GX40: =ROUND(HC40*I40,2) -> 0 | HA40: 0 | HB40: 0 | HC40: =GV40*GW40 -> 0 | IK40: 0
