Workbook

Sheet Смета СН-2012 по гл. 1-5
A1: =CONCATENATE(Source!B1, " СН-2012 (© ОАО МЦЦС 'Мосстройцены', ", "2026", ")") -> Smeta.RU (495) 974-1589 СН-2012 (© ОАО МЦЦС 'Мосстройцены', 2026)
J2: Форма № 1а (глава 1-5)
B3: "СОГЛАСОВАНО" | G3: "УТВЕРЖДАЮ"
B6: =CONCATENATE("______________________ ", IF(Source!AL12<>"", Source!AL12, "")) -> ______________________ | G6: =CONCATENATE("______________________ ", IF(Source!AH12<>"", Source!AH12, "")) -> ______________________
B7: "_____"________________ 2026 г. | G7: "_____"________________ 2026 г.
A10: =CONCATENATE( "ЛОКАЛЬНАЯ СМЕТА № ",IF(Source!F12<>"Новый объект", Source!F12, "")) -> ЛОКАЛЬНАЯ СМЕТА №
A11: (локальный сметный расчет)
A15: =IF(Source!G12<>"Новый объект", Source!G12, "") -> Электрика новая
A16: (наименование работ и затрат, наименование объекта)
A18: =CONCATENATE( "Основание: чертежи № ", Source!J12) -> Основание: чертежи №
F20: Сметная стоимость | I20: =I21+I22+I23+I24 -> 10358.32 | K20: тыс.руб
F21: Строительные работы | I21: =ROUND((Source!F3937)/1000, 2) -> 2489.84 | K21: тыс.руб
F22: Монтажные работы | I22: =ROUND((Source!F3938)/1000, 2) -> 0 | K22: тыс.руб
F23: Оборудование | I23: =ROUND((Source!F3929)/1000, 2) -> 0 | K23: тыс.руб
F24: Прочие работы | I24: =ROUND((Source!F3939+Source!F3940)/1000, 2) -> 7868.48 | K24: тыс.руб
F25: Средства на оплату труда | I25: =(Source!F3935+ Source!F3934)/1000 -> 3759.6864 | K25: тыс.руб
A26: Составлен(а) в уровне текущих (прогнозных) цен на январь 2026 года
A27: №№ п/п | B27: Шифр расценки и коды ресурсов | C27: Наименование работ и затрат | D27: Единица измерения | E27: Кол-во единиц | F27: Цена на ед. изм. руб. | G27: Попра-вочные коэфф. | H27: Коэфф. зимних удоро-жаний | I27: Коэфф. пересчета | J27: ВСЕГО затрат, руб. | K27: Справочно
K28: ЗТР, всего чел.-час
K29: Ст-ть ед. с начислен.
A30: 1 | B30: 2 | C30: 3 | D30: 4 | E30: 5 | F30: 6 | G30: 7 | H30: 8 | I30: 9 | J30: 10 | K30: 11
A32: =CONCATENATE("Локальная смета: ",IF(Source!G20<>"Новая локальная смета", Source!G20, "")) -> Локальная смета:
A34: =CONCATENATE("Раздел: ",IF(Source!G24<>"Новый раздел", Source!G24, "")) -> Раздел: Помещение 312 Актовый зал
A35: 1 | B35: =Source!F28 -> 1.21-3305-1-1/1 | C35: =Source!G28 -> Демонтаж выключателей, розеток | D35: =Source!H28 -> 100 шт. | E35: =Source!I28 -> 0.1 | Q35: =ROUND((Source!BZ28/100)*ROUND((Source!AF28*Source!AV28)*Source!I28, 2), 2) -> 189.74 | R35: =Source!X28 -> 189.74 | S35: =ROUND((Source!CA28/100)*ROUND((Source!AF28*Source!AV28)*Source!I28, 2), 2) -> 27.11 | T35: =Source!Y28 -> 27.11 | U35: =ROUND((175/100)*ROUND((Source!AE28*Source!AV28)*Source!I28, 2), 2) -> 0 | V35: =ROUND((108/100)*ROUND(Source!CS28*Source!I28, 2), 2) -> 0
C36: ="Объем: "&Source!I28&"=10/"&"100" -> Объем: 0,1=10/100
C37: ЗП | F37: =Source!AO28 -> 2710.46 | G37: =Source!DG28 | H37: =Source!AV28 -> 1 | I37: =IF(Source!BA28<> 0, Source!BA28, 1) -> 1 | J37: =Source!S28 -> 271.05
C38: НР от ЗП | D38: % | E38: =Source!AT28 -> 70 | J38: =SUM(R35:R37) -> 189.74
C39: СП от ЗП | D39: % | E39: =Source!AU28 -> 10 | J39: =SUM(T35:T38) -> 27.11
C40: ЗТР | D40: чел-ч | E40: =Source!AQ28 -> 5.84 | G40: =Source!DI28 | H40: =Source!AV28 -> 1 | K40: =Source!U28 -> 0.584
I41: =J37+J38+J39 -> 487.9 | K41: =IF(Source!I28<>0, ROUND(I41/Source!I28, 2), 0) -> 4879 | P41: =I41 -> 487.9
A42: 2 | B42: =Source!F29 -> 1.21-3103-31-2/3 | C42: =Source!G29 -> Прокладка пластикового кабель-канала - по бетонному основанию / сечение 60х40 мм | D42: =Source!H29 -> 100 м | E42: =Source!I29 -> 3.15 | Q42: =ROUND((Source!BZ29/100)*ROUND((Source!AF29*Source!AV29)*Source!I29, 2), 2) -> 58621.89 | R42: =Source!X29 -> 58621.89 | S42: =ROUND((Source!CA29/100)*ROUND((Source!AF29*Source!AV29)*Source!I29, 2), 2) -> 8374.56 | T42: =Source!Y29 -> 8374.56 | U42: =ROUND((175/100)*ROUND((Source!AE29*Source!AV29)*Source!I29, 2), 2) -> 5.13 | V42: =ROUND((108/100)*ROUND(Source!CS29*Source!I29, 2), 2) -> 3.16
C43: ="Объем: "&Source!I29&"=315/"&"100" -> Объем: 3,15=315/100
C44: ЗП | F44: =Source!AO29 -> 26585.89 | G44: =Source!DG29 | H44: =Source!AV29 -> 1 | I44: =IF(Source!BA29<> 0, Source!BA29, 1) -> 1 | J44: =Source!S29 -> 83745.55
C45: ЭМ | F45: =Source!AM29 -> 67.4 | G45: =Source!DE29 | H45: =Source!AV29 -> 1 | I45: =IF(Source!BB29<> 0, Source!BB29, 1) -> 1 | J45: =Source!Q29 -> 212.31
C46: в т.ч. ЗПМ | F46: =Source!AN29 -> 0.93 | G46: =Source!DF29 | H46: =Source!AV29 -> 1 | I46: =IF(Source!BS29<> 0, Source!BS29, 1) -> 1 | J46: =Source!R29 -> 2.93
C47: МР | F47: =Source!AL29 -> 31223.74 | G47: =Source!DD29 | H47: =Source!AW29 -> 1 | I47: =IF(Source!BC29<> 0, Source!BC29, 1) -> 1 | J47: =Source!P29 -> 98354.78
C48: НР от ЗП | D48: % | E48: =Source!AT29 -> 70 | J48: =SUM(R42:R47) -> 58621.89
C49: СП от ЗП | D49: % | E49: =Source!AU29 -> 10 | J49: =SUM(T42:T48) -> 8374.56
C50: НР и СП от ЗПМ | D50: % | E50: =108 -> 108 | J50: =SUM(V42:V49) -> 3.16
C51: ЗТР | D51: чел-ч | E51: =Source!AQ29 -> 46.78 | G51: =Source!DI29 | H51: =Source!AV29 -> 1 | K51: =Source!U29 -> 147.357
...

Sheet Дефектная ведомость
A1: =Source!B1 -> Smeta.RU (495) 974-1589
B3: "СОГЛАСОВАНО" | D3: "УТВЕРЖДАЮ"
B5: ___________________________ | C5: ___________________________
B7: ___________________________ | C7: ___________________________
C9: " ___ " ___________ 20 ___ г.
A11: =CONCATENATE("Дефектный акт ", IF(Source!AN15<>"", Source!AN15," ")) -> Дефектный акт
A12: =CONCATENATE("На капитальный ремонт ", Source!G12) -> На капитальный ремонт Электрика новая
B14: Мы, нижеподписавшиеся, произвели осмотр объекта
B15: и постановили произвести ремонт объекта в
B16: следующем объеме:
A17: № п/п | B17: Наименование работ и затрат | C17: Единица измерения | D17: Количество | E17: Примечание
A18: 1 | B18: 2 | C18: 3 | D18: 4 | E18: 5
A19: =CONCATENATE("Локальная смета: ", Source!G20) -> Локальная смета: Новая локальная смета
A20: =CONCATENATE("Раздел: ", Source!G24) -> Раздел: Помещение 312 Актовый зал
A21: 1 | B21: =Source!G28 -> Демонтаж выключателей, розеток | C21: =Source!H28 -> 100 шт. | D21: =Source!I28 -> 0.1
A22: 2 | B22: =Source!G29 -> Прокладка пластикового кабель-канала - по бетонному основанию / сечение 60х40 мм | C22: =Source!H29 -> 100 м | D22: =Source!I29 -> 3.15
A23: 3 | B23: =Source!G30 -> Прокладка проводов и кабелей в лотках, провод сечением до 6 мм2 | C23: =Source!H30 -> 100 м | D23: =Source!I30 -> 3.15
A24: 4 | B24: =Source!G31 -> Кабели силовые, с медными жилами, с изоляц. и оболоч.из ПВХ пластиката пониж.пожар.опасности, не распростр.горение, с пониж.дымо- и газовыделением и с низк.токсич-тью продуктов горения, напряж.1000 В, марка ВВГнг(А)-LSLTx, число жил и сечение, мм2: 3х2,5 | C24: =Source!H31 -> км | D24: =Source!I31 -> 0.27
A25: 5 | B25: =Source!G32 -> Установка розетки штепсельной неутопленного типа при открытой проводке | C25: =Source!H32 -> 100 шт. | D25: =Source!I32 -> 0.12
A26: 6 | B26: =Source!G33 -> Установка выключателя одноклавишного неутопленного типа при открытой проводке | C26: =Source!H33 -> 100 шт. | D26: =Source!I33 -> 0.02
A27: 7 | B27: =Source!G34 -> Установка выключателя двухклавишного неутопленного типа при открытой проводке | C27: =Source!H34 -> 100 шт. | D27: =Source!I34 -> 0.02
A28: 8 | B28: =Source!G35 -> Установка светильника светодиодного (панели) 595х595 мм в подвесном потолке, устанавливаемого на профиле, со встроенным драйвером / светильник (панель) 595х595х19 мм, 27 Вт, 3000 Лм, 4000 К, IP40 / (демонтаж) | C28: =Source!H35 -> шт. | D28: =Source!I35 -> 22
A29: 9 | B29: =Source!G36 -> Установка светильников с люминесцентными лампами в подвесных потолках, устанавливаемых на подвесках, с количеством ламп в светильнике до 2 | C29: =Source!H36 -> 100 шт. | D29: =Source!I36 -> 0.3
A30: 10 | B30: =Source!G37 -> Разводка по устройствам и подключение жил кабелей или проводов внешней сети к блокам зажимов и к зажимам аппаратов и приборов, установленных на устройствах, кабели и провода сечение до 10 мм2 (без стоимости материалов) | C30: =Source!H37 -> 100 жил | D30: =Source!I37 -> 0.9
A31: =CONCATENATE("Раздел: ", Source!G69) -> Раздел: Электрощит ЩАО (актовый зал)
A32: 11 | B32: =Source!G73 -> Установка выключателя установочного автоматического (автомата) или неавтоматического одно-, двух-, трехполюсного на конструкции на стене или колонне на ток до 100 А (демонтаж) | C32: =Source!H73 -> шт. | D32: =Source!I73 -> 13
A33: 12 | B33: =Source!G74 -> Установка выключателя установочного автоматического (автомата) или неавтоматического одно-, двух-, трехполюсного на конструкции на стене или колонне на ток до 100 А | C33: =Source!H74 -> шт. | D33: =Source!I74 -> 13
A34: 12.1 | B34: =Source!G75 -> Выключатели автоматические, серия "Домовой", трехполюсные, тип ВА 63(С), на ток: 50 А, 63 А | C34: =Source!H75 -> шт. | D34: =Source!I75 -> -13
A35: =CONCATENATE("Раздел: ", Source!G107) -> Раздел: Электрощит ЩО (актовый зал)
A36: 13 | B36: =Source!G111 -> Установка выключателя установочного автоматического (автомата) или неавтоматического одно-, двух-, трехполюсного на конструкции на стене или колонне на ток до 100 А (демонтаж) | C36: =Source!H111 -> шт. | D36: =Source!I111 -> 11
A37: 14 | B37: =Source!G112 -> Установка выключателя установочного автоматического (автомата) или неавтоматического одно-, двух-, трехполюсного на конструкции на стене или колонне на ток до 100 А | C37: =Source!H112 -> шт. | D37: =Source!I112 -> 11
A38: 14.1 | B38: =Source!G113 -> Выключатели автоматические, серия "Домовой", трехполюсные, тип ВА 63(С), на ток: 50 А, 63 А | C38: =Source!H113 -> шт. | D38: =Source!I113 -> -11
A39: =CONCATENATE("Раздел: ", Source!G145) -> Раздел: Электрощит РЩ (актовый зал)
A40: 15 | B40: =Source!G149 -> Установка выключателя установочного автоматического (автомата) или неавтоматического одно-, двух-, трехполюсного на конструкции на стене или колонне на ток до 100 А (демонтаж) | C40: =Source!H149 -> шт. | D40: =Source!I149 -> 11
A41: 16 | B41: =Source!G150 -> Установка выключателя установочного автоматического (автомата) или неавтоматического одно-, двух-, трехполюсного на конструкции на стене или колонне на ток до 100 А | C41: =Source!H150 -> шт. | D41: =Source!I150 -> 11
A42: 16.1 | B42: =Source!G151 -> Выключатели автоматические, серия "Домовой", трехполюсные, тип ВА 63(С), на ток: 50 А, 63 А | C42: =Source!H151 -> шт. | D42: =Source!I151 -> -11
A43: =CONCATENATE("Раздел: ", Source!G183) -> Раздел: Помещение 108 Обеденный зал с умывальником
A44: 17 | B44: =Source!G187 -> Демонтаж выключателей, розеток | C44: =Source!H187 -> 100 шт. | D44: =Source!I187 -> 0.12
A45: 18 | B45: =Source!G188 -> Установка розетки штепсельной неутопленного типа при открытой проводке | C45: =Source!H188 -> 100 шт. | D45: =Source!I188 -> 0.1
A46: 19 | B46: =Source!G189 -> Установка выключателя одноклавишного неутопленного типа при открытой проводке | C46: =Source!H189 -> 100 шт. | D46: =Source!I189 -> 0.01
...

Sheet RV_DATA
A1: BuildingFinished | B1: Trud | C1: Mash | D1: Mat | E1: MatZak | F1: Oborud | G1: OborudZak | H1: ZeroStoim | I1: NegativeKoll | J1: ReUnionKollResurcy | K1: UnionOneUchRes | L1: IdLevel | M1: ViewCodes | N1: UnionCodes | O1: PEREVOZKA
A2: 1 | B2: 0 | C2: 0 | D2: 1 | E2: 1 | F2: 1 | G2: 1 | H2: 0 | I2: 1 | J2: 0 | K2: 1 | L2: 35364244 | M2: 0 | N2: 0 | O2: 0
A4: TYPE | B4: SOURCE_LINK | C4: RABMAT_EX | D4: TIP_RAB | E4: TYPE_TRUD | F4: TAB | G4: NAME | H4: EDIZM | I4: KOLL | J4: UCH | K4: PRICE_B | L4: PRICE_ED | M4: STOIM_B | N4: PRICE_C | O4: STOIM_C | P4: ZPM_B | Q4: ZPM_ED | R4: STOIM_ZPM_B | S4: ZPM_C | T4: STOIM_ZPM_C | U4: RABMAT | V4: WBS | W4: CBSI | X4: CBSII | Y4: TechSpecCVORPP | Z4: CRC_GR_RES | AA4: CRC_B | AB4: CRC_C
A6: =Source!A20 -> 3 | B6: 20 | G6: =Source!G20 -> Новая локальная смета
A7: =Source!A24 -> 4 | B7: 24 | G7: =Source!G24 -> Помещение 312 Актовый зал
A8: 20 | B8: 14 | C8: 3 | D8: 0 | E8: =SmtRes!AV14 -> 0 | F8: =SmtRes!I14 -> 21.7-3-54 | G8: =SmtRes!K14 -> Сверло с алмазным покрытием, диаметр 6 мм | H8: =SmtRes!O14 -> шт. | I8: =SmtRes!Y14*Source!I29 -> 12.6 | J8: =SmtRes!AO14 -> 1 | K8: =SmtRes!AE14 -> 1555.5 | L8: =SmtRes!DB14 -> 6222 | M8: =ROUND(ROUND(L8*Source!I29, 6)*1, 2) -> 19599.3 | N8: =SmtRes!AA14 -> 1555.5 | O8: =ROUND(ROUND(L8*Source!I29, 6)*SmtRes!DA14, 2) -> 19599.3 | P8: =SmtRes!AG14 -> 0 | Q8: =SmtRes!DC14 -> 0 | R8: =ROUND(ROUND(Q8*Source!I29, 6)*1, 2) -> 0 | S8: =SmtRes!AC14 -> 0 | T8: =ROUND(ROUND(Q8*Source!I29, 6)*SmtRes!AK14, 2) -> 0 | U8: 3 | Z8: =SmtRes!X14 -> 1662095060 | AA8: -618828638 | AB8: -618828638
A9: 20 | B9: 13 | C9: 3 | D9: 0 | E9: =SmtRes!AV13 -> 0 | F9: =SmtRes!I13 -> 21.1-25-1034 | G9: =SmtRes!K13 -> Кабель-каналы, размер 60х40 мм: углы плоские | H9: =SmtRes!O13 -> шт. | I9: =SmtRes!Y13*Source!I29 -> 6.3 | J9: =SmtRes!AO13 -> 1 | K9: =SmtRes!AE13 -> 214.92 | L9: =SmtRes!DB13 -> 429.84 | M9: =ROUND(ROUND(L9*Source!I29, 6)*1, 2) -> 1354 | N9: =SmtRes!AA13 -> 214.92 | O9: =ROUND(ROUND(L9*Source!I29, 6)*SmtRes!DA13, 2) -> 1354 | P9: =SmtRes!AG13 -> 0 | Q9: =SmtRes!DC13 -> 0 | R9: =ROUND(ROUND(Q9*Source!I29, 6)*1, 2) -> 0 | S9: =SmtRes!AC13 -> 0 | T9: =ROUND(ROUND(Q9*Source!I29, 6)*SmtRes!AK13, 2) -> 0 | U9: 3 | Z9: =SmtRes!X13 -> -1452375277 | AA9: 1614893387 | AB9: 1614893387
A10: 20 | B10: 12 | C10: 3 | D10: 0 | E10: =SmtRes!AV12 -> 0 | F10: =SmtRes!I12 -> 21.1-25-1033 | G10: =SmtRes!K12 -> Кабель-каналы, размер 60х40 мм: углы наружные | H10: =SmtRes!O12 -> шт. | I10: =SmtRes!Y12*Source!I29 -> 47.25 | J10: =SmtRes!AO12 -> 1 | K10: =SmtRes!AE12 -> 203.06 | L10: =SmtRes!DB12 -> 3045.9 | M10: =ROUND(ROUND(L10*Source!I29, 6)*1, 2) -> 9594.59 | N10: =SmtRes!AA12 -> 203.06 | O10: =ROUND(ROUND(L10*Source!I29, 6)*SmtRes!DA12, 2) -> 9594.59 | P10: =SmtRes!AG12 -> 0 | Q10: =SmtRes!DC12 -> 0 | R10: =ROUND(ROUND(Q10*Source!I29, 6)*1, 2) -> 0 | S10: =SmtRes!AC12 -> 0 | T10: =ROUND(ROUND(Q10*Source!I29, 6)*SmtRes!AK12, 2) -> 0 | U10: 3 | Z10: =SmtRes!X12 -> 1479709201 | AA10: -124735961 | AB10: -124735961
A11: 20 | B11: 11 | C11: 3 | D11: 0 | E11: =SmtRes!AV11 -> 0 | F11: =SmtRes!I11 -> 21.1-25-1032 | G11: =SmtRes!K11 -> Кабель-каналы, размер 60х40 мм: углы внутренние | H11: =SmtRes!O11 -> шт. | I11: =SmtRes!Y11*Source!I29 -> 6.3 | J11: =SmtRes!AO11 -> 1 | K11: =SmtRes!AE11 -> 186.55 | L11: =SmtRes!DB11 -> 373.1 | M11: =ROUND(ROUND(L11*Source!I29, 6)*1, 2) -> 1175.27 | N11: =SmtRes!AA11 -> 186.55 | O11: =ROUND(ROUND(L11*Source!I29, 6)*SmtRes!DA11, 2) -> 1175.27 | P11: =SmtRes!AG11 -> 0 | Q11: =SmtRes!DC11 -> 0 | R11: =ROUND(ROUND(Q11*Source!I29, 6)*1, 2) -> 0 | S11: =SmtRes!AC11 -> 0 | T11: =ROUND(ROUND(Q11*Source!I29, 6)*SmtRes!AK11, 2) -> 0 | U11: 3 | Z11: =SmtRes!X11 -> -32305080 | AA11: -1064398607 | AB11: -1064398607
A12: 20 | B12: 10 | C12: 3 | D12: 0 | E12: =SmtRes!AV10 -> 0 | F12: =SmtRes!I10 -> 21.1-25-1031 | G12: =SmtRes!K10 -> Кабель-каналы, размер 60х40 мм: тройники | H12: =SmtRes!O10 -> шт. | I12: =SmtRes!Y10*Source!I29 -> 6.3 | J12: =SmtRes!AO10 -> 1 | K12: =SmtRes!AE10 -> 219.52 | L12: =SmtRes!DB10 -> 439.04 | M12: =ROUND(ROUND(L12*Source!I29, 6)*1, 2) -> 1382.98 | N12: =SmtRes!AA10 -> 219.52 | O12: =ROUND(ROUND(L12*Source!I29, 6)*SmtRes!DA10, 2) -> 1382.98 | P12: =SmtRes!AG10 -> 0 | Q12: =SmtRes!DC10 -> 0 | R12: =ROUND(ROUND(Q12*Source!I29, 6)*1, 2) -> 0 | S12: =SmtRes!AC10 -> 0 | T12: =ROUND(ROUND(Q12*Source!I29, 6)*SmtRes!AK10, 2) -> 0 | U12: 3 | Z12: =SmtRes!X10 -> 1816340030 | AA12: -1841828503 | AB12: -1841828503
A13: 20 | B13: 9 | C13: 3 | D13: 0 | E13: =SmtRes!AV9 -> 0 | F13: =SmtRes!I9 -> 21.1-25-1029 | G13: =SmtRes!K9 -> Кабель-каналы, размер 60х40 мм: накладки стыковые | H13: =SmtRes!O9 -> шт. | I13: =SmtRes!Y9*Source!I29 -> 12.6 | J13: =SmtRes!AO9 -> 1 | K13: =SmtRes!AE9 -> 126.89 | L13: =SmtRes!DB9 -> 507.56 | M13: =ROUND(ROUND(L13*Source!I29, 6)*1, 2) -> 1598.81 | N13: =SmtRes!AA9 -> 126.89 | O13: =ROUND(ROUND(L13*Source!I29, 6)*SmtRes!DA9, 2) -> 1598.81 | P13: =SmtRes!AG9 -> 0 | Q13: =SmtRes!DC9 -> 0 | R13: =ROUND(ROUND(Q13*Source!I29, 6)*1, 2) -> 0 | S13: =SmtRes!AC9 -> 0 | T13: =ROUND(ROUND(Q13*Source!I29, 6)*SmtRes!AK9, 2) -> 0 | U13: 3 | Z13: =SmtRes!X9 -> -1376764488 | AA13: 1140495319 | AB13: 1140495319
A14: 20 | B14: 8 | C14: 3 | D14: 0 | E14: =SmtRes!AV8 -> 0 | F14: =SmtRes!I8 -> 21.1-25-1028 | G14: =SmtRes!K8 -> Кабель-каналы, размер 60х40 мм: заглушки | H14: =SmtRes!O8 -> шт. | I14: =SmtRes!Y8*Source!I29 -> 47.25 | J14: =SmtRes!AO8 -> 1 | K14: =SmtRes!AE8 -> 145.46 | L14: =SmtRes!DB8 -> 2181.9 | M14: =ROUND(ROUND(L14*Source!I29, 6)*1, 2) -> 6872.99 | N14: =SmtRes!AA8 -> 145.46 | O14: =ROUND(ROUND(L14*Source!I29, 6)*SmtRes!DA8, 2) -> 6872.99 | P14: =SmtRes!AG8 -> 0 | Q14: =SmtRes!DC8 -> 0 | R14: =ROUND(ROUND(Q14*Source!I29, 6)*1, 2) -> 0 | S14: =SmtRes!AC8 -> 0 | T14: =ROUND(ROUND(Q14*Source!I29, 6)*SmtRes!AK8, 2) -> 0 | U14: 3 | Z14: =SmtRes!X8 -> -1986506557 | AA14: 368106192 | AB14: 368106192
A15: 20 | B15: 7 | C15: 3 | D15: 0 | E15: =SmtRes!AV7 -> 0 | F15: =SmtRes!I7 -> 21.1-25-1027 | G15: =SmtRes!K7 -> Кабель-каналы, размер 60х40 мм: кабель-каналы | H15: =SmtRes!O7 -> м | I15: =SmtRes!Y7*Source!I29 -> 315 | J15: =SmtRes!AO7 -> 1 | K15: =SmtRes!AE7 -> 138.94 | L15: =SmtRes!DB7 -> 13894 | M15: =ROUND(ROUND(L15*Source!I29, 6)*1, 2) -> 43766.1 | N15: =SmtRes!AA7 -> 138.94 | O15: =ROUND(ROUND(L15*Source!I29, 6)*SmtRes!DA7, 2) -> 43766.1 | P15: =SmtRes!AG7 -> 0 | Q15: =SmtRes!DC7 -> 0 | R15: =ROUND(ROUND(Q15*Source!I29, 6)*1, 2) -> 0 | S15: =SmtRes!AC7 -> 0 | T15: =ROUND(ROUND(Q15*Source!I29, 6)*SmtRes!AK7, 2) -> 0 | U15: 3 | Z15: =SmtRes!X7 -> 1471616812 | AA15: -402984879 | AB15: -402984879
A16: 20 | B16: 6 | C16: 3 | D16: 0 | E16: =SmtRes!AV6 -> 0 | F16: =SmtRes!I6 -> 21.1-11-81 | G16: =SmtRes!K6 -> Патроны, калибр 6,8/11 М для дюбеля | H16: =SmtRes!O6 -> 100 шт. | I16: =SmtRes!Y6*Source!I29 -> 12.6 | J16: =SmtRes!AO6 -> 1 | K16: =SmtRes!AE6 -> 997.35 | L16: =SmtRes!DB6 -> 3989.4 | M16: =ROUND(ROUND(L16*Source!I29, 6)*1, 2) -> 12566.61 | N16: =SmtRes!AA6 -> 997.35 | O16: =ROUND(ROUND(L16*Source!I29, 6)*SmtRes!DA6, 2) -> 12566.61 | P16: =SmtRes!AG6 -> 0 | Q16: =SmtRes!DC6 -> 0 | R16: =ROUND(ROUND(Q16*Source!I29, 6)*1, 2) -> 0 | S16: =SmtRes!AC6 -> 0 | T16: =ROUND(ROUND(Q16*Source!I29, 6)*SmtRes!AK6, 2) -> 0 | U16: 3 | Z16: =SmtRes!X6 -> 1583670906 | AA16: -274985448 | AB16: -274985448
A17: 20 | B17: 5 | C17: 3 | D17: 0 | E17: =SmtRes!AV5 -> 0 | F17: =SmtRes!I5 -> 21.1-11-108 | G17: =SmtRes!K5 -> Шурупы-саморезы, размер 3,5х45 мм | H17: =SmtRes!O5 -> т | I17: =SmtRes!Y5*Source!I29 -> 0.002331 | J17: =SmtRes!AO5 -> 1 | K17: =SmtRes!AE5 -> 190540.34 | L17: =SmtRes!DB5 -> 141 | M17: =ROUND(ROUND(L17*Source!I29, 6)*1, 2) -> 444.15 | N17: =SmtRes!AA5 -> 190540.34 | O17: =ROUND(ROUND(L17*Source!I29, 6)*SmtRes!DA5, 2) -> 444.15 | P17: =SmtRes!AG5 -> 0 | Q17: =SmtRes!DC5 -> 0 | R17: =ROUND(ROUND(Q17*Source!I29, 6)*1, 2) -> 0 | S17: =SmtRes!AC5 -> 0 | T17: =ROUND(ROUND(Q17*Source!I29, 6)*SmtRes!AK5, 2) -> 0 | U17: 3 | Z17: =SmtRes!X5 -> -181271767 | AA17: -2066596354 | AB17: -2066596354
A18: 20 | B18: 23 | C18: 3 | D18: 0 | E18: =SmtRes!AV23 -> 0 | F18: =SmtRes!I23 -> 21.23-13-14 | G18: =SmtRes!K23 -> Провода силовые с медными жилами в поливинилхлоридной изоляции, марка ПуГВ, номинальное напряжение до 450 В, число жил и сечение 1х6 мм2 | H18: =SmtRes!O23 -> км | I18: =SmtRes!Y23*Source!I30 -> 0.32445 | J18: =SmtRes!AO23 -> 1 | K18: =SmtRes!AE23 -> 99643.05 | L18: =SmtRes!DB23 -> 10263.23 | M18: =ROUND(ROUND(L18*Source!I30, 6)*1, 2) -> 32329.17 | N18: =SmtRes!AA23 -> 99643.05 | O18: =ROUND(ROUND(L18*Source!I30, 6)*SmtRes!DA23, 2) -> 32329.17 | P18: =SmtRes!AG23 -> 0 | Q18: =SmtRes!DC23 -> 0 | R18: =ROUND(ROUND(Q18*Source!I30, 6)*1, 2) -> 0 | S18: =SmtRes!AC23 -> 0 | T18: =ROUND(ROUND(Q18*Source!I30, 6)*SmtRes!AK23, 2) -> 0 | U18: 3 | Z18: =SmtRes!X23 -> 1173250179 | AA18: -458052105 | AB18: -458052105
A19: 20 | B19: 22 | C19: 3 | D19: 0 | E19: =SmtRes!AV22 -> 0 | F19: =SmtRes!I22 -> 21.21-5-44 | G19: =SmtRes!K22 -> Кнопки для ленты ЛМ, тип 3,5 | H19: =SmtRes!O22 -> 1000 шт. | I19: =SmtRes!Y22*Source!I30 -> 0.063 | J19: =SmtRes!AO22 -> 1 | K19: =SmtRes!AE22 -> 258.44 | L19: =SmtRes!DB22 -> 5.17 | M19: =ROUND(ROUND(L19*Source!I30, 6)*1, 2) -> 16.29 | N19: =SmtRes!AA22 -> 258.44 | O19: =ROUND(ROUND(L19*Source!I30, 6)*SmtRes!DA22, 2) -> 16.29 | P19: =SmtRes!AG22 -> 0 | Q19: =SmtRes!DC22 -> 0 | R19: =ROUND(ROUND(Q19*Source!I30, 6)*1, 2) -> 0 | S19: =SmtRes!AC22 -> 0 | T19: =ROUND(ROUND(Q19*Source!I30, 6)*SmtRes!AK22, 2) -> 0 | U19: 3 | Z19: =SmtRes!X22 -> -1680055193 | AA19: -2054620093 | AB19: -2054620093
A20: 20 | B20: 21 | C20: 3 | D20: 0 | E20: =SmtRes!AV21 -> 0 | F20: =SmtRes!I21 -> 21.21-5-342 | G20: =SmtRes!K21 -> Хомуты (стяжки) кабельные из полиамида, размеры 3,6х200 мм | H20: =SmtRes!O21 -> 100 шт. | I20: =SmtRes!Y21*Source!I30 -> 0.819 | J20: =SmtRes!AO21 -> 1 | K20: =SmtRes!AE21 -> 127.48 | L20: =SmtRes!DB21 -> 33.14 | M20: =ROUND(ROUND(L20*Source!I30, 6)*1, 2) -> 104.39 | N20: =SmtRes!AA21 -> 127.48 | O20: =ROUND(ROUND(L20*Source!I30, 6)*SmtRes!DA21, 2) -> 104.39 | P20: =SmtRes!AG21 -> 0 | Q20: =SmtRes!DC21 -> 0 | R20: =ROUND(ROUND(Q20*Source!I30, 6)*1, 2) -> 0 | S20: =SmtRes!AC21 -> 0 | T20: =ROUND(ROUND(Q20*Source!I30, 6)*SmtRes!AK21, 2) -> 0 | U20: 3 | Z20: =SmtRes!X21 -> 527662241 | AA20: -1533345047 | AB20: -1533345047
A21: 20 | B21: 20 | C21: 3 | D21: 0 | E21: =SmtRes!AV20 -> 0 | F21: =SmtRes!I20 -> 21.21-5-305 | G21: =SmtRes!K20 -> Сжимы, тип У731М для проводников магистральных сечением от 4 до 10 мм2 и ответвительных от 1,5 до 10 мм2 | H21: =SmtRes!O20 -> шт. | I21: =SmtRes!Y20*Source!I30 -> 31.5 | J21: =SmtRes!AO20 -> 1 | K21: =SmtRes!AE20 -> 29.36 | L21: =SmtRes!DB20 -> 293.6 | M21: =ROUND(ROUND(L21*Source!I30, 6)*1, 2) -> 924.84 | N21: =SmtRes!AA20 -> 29.36 | O21: =ROUND(ROUND(L21*Source!I30, 6)*SmtRes!DA20, 2) -> 924.84 | P21: =SmtRes!AG20 -> 0 | Q21: =SmtRes!DC20 -> 0 | R21: =ROUND(ROUND(Q21*Source!I30, 6)*1, 2) -> 0 | S21: =SmtRes!AC20 -> 0 | T21: =ROUND(ROUND(Q21*Source!I30, 6)*SmtRes!AK20, 2) -> 0 | U21: 3 | Z21: =SmtRes!X20 -> 1884843886 | AA21: 1143219249 | AB21: 1143219249
A22: 20 | B22: 19 | C22: 3 | D22: 0 | E22: =SmtRes!AV19 -> 0 | F22: =SmtRes!I19 -> 21.21-5-2 | G22: =SmtRes!K19 -> Бирки маркировочные для кабелей и проводов, тип У153 У3,5 | H22: =SmtRes!O19 -> 1000 шт. | I22: =SmtRes!Y19*Source!I30 -> 0.01575 | J22: =SmtRes!AO19 -> 1 | K22: =SmtRes!AE19 -> 718.56 | L22: =SmtRes!DB19 -> 3.59 | M22: =ROUND(ROUND(L22*Source!I30, 6)*1, 2) -> 11.31 | N22: =SmtRes!AA19 -> 718.56 | O22: =ROUND(ROUND(L22*Source!I30, 6)*SmtRes!DA19, 2) -> 11.31 | P22: =SmtRes!AG19 -> 0 | Q22: =SmtRes!DC19 -> 0 | R22: =ROUND(ROUND(Q22*Source!I30, 6)*1, 2) -> 0 | S22: =SmtRes!AC19 -> 0 | T22: =ROUND(ROUND(Q22*Source!I30, 6)*SmtRes!AK19, 2) -> 0 | U22: 3 | Z22: =SmtRes!X19 -> -1948375318 | AA22: 299589489 | AB22: 299589489
A23: 20 | B23: 18 | C23: 3 | D23: 0 | E23: =SmtRes!AV18 -> 0 | F23: =SmtRes!I18 -> 21.21-5-114 | G23: =SmtRes!K18 -> Лента монтажная, тип ЛМ-5 | H23: =SmtRes!O18 -> м | I23: =SmtRes!Y18*Source!I30 -> 15.75 | J23: =SmtRes!AO18 -> 1 | K23: =SmtRes!AE18 -> 5.71 | L23: =SmtRes!DB18 -> 28.55 | M23: =ROUND(ROUND(L23*Source!I30, 6)*1, 2) -> 89.93 | N23: =SmtRes!AA18 -> 5.71 | O23: =ROUND(ROUND(L23*Source!I30, 6)*SmtRes!DA18, 2) -> 89.93 | P23: =SmtRes!AG18 -> 0 | Q23: =SmtRes!DC18 -> 0 | R23: =ROUND(ROUND(Q23*Source!I30, 6)*1, 2) -> 0 | S23: =SmtRes!AC18 -> 0 | T23: =ROUND(ROUND(Q23*Source!I30, 6)*SmtRes!AK18, 2) -> 0 | U23: 3 | Z23: =SmtRes!X18 -> -1189895200 | AA23: 193152040 | AB23: 193152040
A24: 20 | B24: 17 | C24: 3 | D24: 0 | E24: =SmtRes!AV17 -> 0 | F24: =SmtRes!I17 -> 21.1-20-10 | G24: =SmtRes!K17 -> Лента изоляционная хлопчатобумажная | H24: =SmtRes!O17 -> кг | I24: =SmtRes!Y17*Source!I30 -> 0.504 | J24: =SmtRes!AO17 -> 1 | K24: =SmtRes!AE17 -> 363.22 | L24: =SmtRes!DB17 -> 58.12 | M24: =ROUND(ROUND(L24*Source!I30, 6)*1, 2) -> 183.08 | N24: =SmtRes!AA17 -> 363.22 | O24: =ROUND(ROUND(L24*Source!I30, 6)*SmtRes!DA17, 2) -> 183.08 | P24: =SmtRes!AG17 -> 0 | Q24: =SmtRes!DC17 -> 0 | R24: =ROUND(ROUND(Q24*Source!I30, 6)*1, 2) -> 0 | S24: =SmtRes!AC17 -> 0 | T24: =ROUND(ROUND(Q24*Source!I30, 6)*SmtRes!AK17, 2) -> 0 | U24: 3 | Z24: =SmtRes!X17 -> 1719425291 | AA24: -1596111638 | AB24: -1596111638
A25: =Source!A31 -> 17 | B25: 31 | C25: 3 | D25: =Source!BI31 -> 4 | E25: =Source!FS31 -> 0 | F25: =Source!F31 -> 21.23-8-270 | G25: =Source!G31 -> Кабели силовые, с медными жилами, с изоляц. и оболоч.из ПВХ пластиката пониж.пожар.опасности, не распростр.горение, с пониж.дымо- и газовыделением и с низк.токсич-тью продуктов горения, напряж.1000 В, марка ВВГнг(А)-LSLTx, число жил и сечение, мм2: 3х2,5 | H25: =Source!H31 -> км | I25: =Source!I31 -> 0.27 | J25: 1 | K25: =Source!AC31 -> 129532.62 | M25: =ROUND(K25*I25, 2) -> 34973.81 | N25: =Source!AC31*IF(Source!BC31<> 0, Source!BC31, 1) -> 129532.62 | O25: =ROUND(N25*I25, 2) -> 34973.81 | P25: =Source!AE31 -> 0 | R25: =ROUND(P25*I25, 2) -> 0 | S25: =Source!AE31*IF(Source!BS31<> 0, Source!BS31, 1) -> 0 | T25: =ROUND(S25*I25, 2) -> 0 | U25: 3 | Z25: =Source!GF31 -> 7717958 | AA25: 2094450950 | AB25: 2094450950
A26: 20 | B26: 44 | C26: 3 | D26: 0 | E26: =SmtRes!AV44 -> 0 | F26: =SmtRes!I44 -> 21.7-4-15 | G26: =SmtRes!K44 -> Профили стоек металлические для монтажа гипсовых перегородок и подвесных потолков стальные, оцинкованные, марка ПСЭ-2, сечение 50х35х0,55 мм | H26: =SmtRes!O44 -> т | I26: =SmtRes!Y44*Source!I36 -> 0.0108 | J26: =SmtRes!AO44 -> 1 | K26: =SmtRes!AE44 -> 40246.74 | L26: =SmtRes!DB44 -> 1448.88 | M26: =ROUND(ROUND(L26*Source!I36, 6)*1, 2) -> 434.66 | N26: =SmtRes!AA44 -> 40246.74 | O26: =ROUND(ROUND(L26*Source!I36, 6)*SmtRes!DA44, 2) -> 434.66 | P26: =SmtRes!AG44 -> 0 | Q26: =SmtRes!DC44 -> 0 | R26: =ROUND(ROUND(Q26*Source!I36, 6)*1, 2) -> 0 | S26: =SmtRes!AC44 -> 0 | T26: =ROUND(ROUND(Q26*Source!I36, 6)*SmtRes!AK44, 2) -> 0 | U26: 3 | Z26: =SmtRes!X44 -> -493677975 | AA26: 162372630 | AB26: 162372630
A27: 20 | B27: 43 | C27: 3 | D27: 0 | E27: =SmtRes!AV43 -> 0 | F27: =SmtRes!I43 -> 21.23-8-258 | G27: =SmtRes!K43 -> Кабели силовые с медными жилами с поливинилхлоридной изоляцией в оболочке из поливинилхлоридного пластиката пониженной горючести, напряжение 660 В, марка ВВГнг(А), число жил и сечение, мм2: 1х 4 | H27: =SmtRes!O43 -> км | I27: =SmtRes!Y43*Source!I36 -> 0.0108 | J27: =SmtRes!AO43 -> 1 | K27: =SmtRes!AE43 -> 47900.07 | L27: =SmtRes!DB43 -> 1724.4 | M27: =ROUND(ROUND(L27*Source!I36, 6)*1, 2) -> 517.32 | N27: =SmtRes!AA43 -> 47900.07 | O27: =ROUND(ROUND(L27*Source!I36, 6)*SmtRes!DA43, 2) -> 517.32 | P27: =SmtRes!AG43 -> 0 | Q27: =SmtRes!DC43 -> 0 | R27: =ROUND(ROUND(Q27*Source!I36, 6)*1, 2) -> 0 | S27: =SmtRes!AC43 -> 0 | T27: =ROUND(ROUND(Q27*Source!I36, 6)*SmtRes!AK43, 2) -> 0 | U27: 3 | Z27: =SmtRes!X43 -> 286422571 | AA27: 249487062 | AB27: 249487062
A28: 20 | B28: 42 | C28: 3 | D28: 0 | E28: =SmtRes!AV42 -> 0 | F28: =SmtRes!I42 -> 21.1-6-37 | G28: =SmtRes!K42 -> Краски водно-дисперсионные поливинилацетатные, белые, марка ВД-ВА-17 | H28: =SmtRes!O42 -> т | I28: =SmtRes!Y42*Source!I36 -> 0.0009 | J28: =SmtRes!AO42 -> 1 | K28: =SmtRes!AE42 -> 75121.86 | L28: =SmtRes!DB42 -> 225.37 | M28: =ROUND(ROUND(L28*Source!I36, 6)*1, 2) -> 67.61 | N28: =SmtRes!AA42 -> 75121.86 | O28: =ROUND(ROUND(L28*Source!I36, 6)*SmtRes!DA42, 2) -> 67.61 | P28: =SmtRes!AG42 -> 0 | Q28: =SmtRes!DC42 -> 0 | R28: =ROUND(ROUND(Q28*Source!I36, 6)*1, 2) -> 0 | S28: =SmtRes!AC42 -> 0 | T28: =ROUND(ROUND(Q28*Source!I36, 6)*SmtRes!AK42, 2) -> 0 | U28: 3 | Z28: =SmtRes!X42 -> -794464499 | AA28: 266707854 | AB28: 266707854
A29: 20 | B29: 41 | C29: 3 | D29: 0 | E29: =SmtRes!AV41 -> 0 | F29: =SmtRes!I41 -> 21.1-23-9 | G29: =SmtRes!K41 -> Электроды, тип Э-42, 46, 50, диаметр 4 - 6 мм | H29: =SmtRes!O41 -> т | I29: =SmtRes!Y41*Source!I36 -> 0.00063 | J29: =SmtRes!AO41 -> 1 | K29: =SmtRes!AE41 -> 109992.36 | L29: =SmtRes!DB41 -> 230.98 | M29: =ROUND(ROUND(L29*Source!I36, 6)*1, 2) -> 69.29 | N29: =SmtRes!AA41 -> 109992.36 | O29: =ROUND(ROUND(L29*Source!I36, 6)*SmtRes!DA41, 2) -> 69.29 | P29: =SmtRes!AG41 -> 0 | Q29: =SmtRes!DC41 -> 0 | R29: =ROUND(ROUND(Q29*Source!I36, 6)*1, 2) -> 0 | S29: =SmtRes!AC41 -> 0 | T29: =ROUND(ROUND(Q29*Source!I36, 6)*SmtRes!AK41, 2) -> 0 | U29: 3 | Z29: =SmtRes!X41 -> 277207382 | AA29: 1948239711 | AB29: 1948239711
A30: 20 | B30: 40 | C30: 3 | D30: 0 | E30: =SmtRes!AV40 -> 0 | F30: =SmtRes!I40 -> 21.1-20-10 | G30: =SmtRes!K40 -> Лента изоляционная хлопчатобумажная | H30: =SmtRes!O40 -> кг | I30: =SmtRes!Y40*Source!I36 -> 0.126 | J30: =SmtRes!AO40 -> 1 | K30: =SmtRes!AE40 -> 363.22 | L30: =SmtRes!DB40 -> 152.55 | M30: =ROUND(ROUND(L30*Source!I36, 6)*1, 2) -> 45.77 | N30: =SmtRes!AA40 -> 363.22 | O30: =ROUND(ROUND(L30*Source!I36, 6)*SmtRes!DA40, 2) -> 45.77 | P30: =SmtRes!AG40 -> 0 | Q30: =SmtRes!DC40 -> 0 | R30: =ROUND(ROUND(Q30*Source!I36, 6)*1, 2) -> 0 | S30: =SmtRes!AC40 -> 0 | T30: =ROUND(ROUND(Q30*Source!I36, 6)*SmtRes!AK40, 2) -> 0 | U30: 3 | Z30: =SmtRes!X40 -> 1719425291 | AA30: -1596111638 | AB30: -1596111638
A31: 20 | B31: 39 | C31: 3 | D31: 0 | E31: =SmtRes!AV39 -> 0 | F31: =SmtRes!I39 -> 21.1-11-21 | G31: =SmtRes!K39 -> Болты строительные черные с гайками и шайбами (10х100мм) | H31: =SmtRes!O39 -> т | I31: =SmtRes!Y39*Source!I36 -> 0.00312 | J31: =SmtRes!AO39 -> 1 | K31: =SmtRes!AE39 -> 161977.32 | L31: =SmtRes!DB39 -> 1684.56 | M31: =ROUND(ROUND(L31*Source!I36, 6)*1, 2) -> 505.37 | N31: =SmtRes!AA39 -> 161977.32 | O31: =ROUND(ROUND(L31*Source!I36, 6)*SmtRes!DA39, 2) -> 505.37 | P31: =SmtRes!AG39 -> 0 | Q31: =SmtRes!DC39 -> 0 | R31: =ROUND(ROUND(Q31*Source!I36, 6)*1, 2) -> 0 | S31: =SmtRes!AC39 -> 0 | T31: =ROUND(ROUND(Q31*Source!I36, 6)*SmtRes!AK39, 2) -> 0 | U31: 3 | Z31: =SmtRes!X39 -> 1955262950 | AA31: -1191326009 | AB31: -1191326009
A32: 20 | B32: 38 | C32: 3 | D32: 0 | E32: =SmtRes!AV38 -> 0 | F32: =SmtRes!I38 -> 21.1-11-198 | G32: =SmtRes!K38 -> Дюбели пластмассовые | H32: =SmtRes!O38 -> шт. | I32: =SmtRes!Y38*Source!I36 -> 45.9 | J32: =SmtRes!AO38 -> 1 | K32: =SmtRes!AE38 -> 1.23 | L32: =SmtRes!DB38 -> 188.19 | M32: =ROUND(ROUND(L32*Source!I36, 6)*1, 2) -> 56.46 | N32: =SmtRes!AA38 -> 1.23 | O32: =ROUND(ROUND(L32*Source!I36, 6)*SmtRes!DA38, 2) -> 56.46 | P32: =SmtRes!AG38 -> 0 | Q32: =SmtRes!DC38 -> 0 | R32: =ROUND(ROUND(Q32*Source!I36, 6)*1, 2) -> 0 | S32: =SmtRes!AC38 -> 0 | T32: =ROUND(ROUND(Q32*Source!I36, 6)*SmtRes!AK38, 2) -> 0 | U32: 3 | Z32: =SmtRes!X38 -> 136717287 | AA32: 798392207 | AB32: 798392207
A33: 20 | B33: 37 | C33: 3 | D33: 0 | E33: =SmtRes!AV37 -> 0 | F33: =SmtRes!I37 -> 21.1-11-133 | G33: =SmtRes!K37 -> Дюбель-гвоздь с патроном | H33: =SmtRes!O37 -> шт. | I33: =SmtRes!Y37*Source!I36 -> 45.9 | J33: =SmtRes!AO37 -> 1 | K33: =SmtRes!AE37 -> 10.83 | L33: =SmtRes!DB37 -> 1656.99 | M33: =ROUND(ROUND(L33*Source!I36, 6)*1, 2) -> 497.1 | N33: =SmtRes!AA37 -> 10.83 | O33: =ROUND(ROUND(L33*Source!I36, 6)*SmtRes!DA37, 2) -> 497.1 | P33: =SmtRes!AG37 -> 0 | Q33: =SmtRes!DC37 -> 0 | R33: =ROUND(ROUND(Q33*Source!I36, 6)*1, 2) -> 0 | S33: =SmtRes!AC37 -> 0 | T33: =ROUND(ROUND(Q33*Source!I36, 6)*SmtRes!AK37, 2) -> 0 | U33: 3 | Z33: =SmtRes!X37 -> -795121688 | AA33: -503754449 | AB33: -503754449
A34: 20 | B34: 36 | C34: 3 | D34: 0 | E34: =SmtRes!AV36 -> 0 | F34: =SmtRes!I36 -> 21.1-10-159 | G34: =SmtRes!K36 -> Сталь круглая и квадратная общего назначения углеродистая кипящая, марка Ст0, размер 5-12 мм | H34: =SmtRes!O36 -> т | I34: =SmtRes!Y36*Source!I36 -> 0.168 | J34: =SmtRes!AO36 -> 1 | K34: =SmtRes!AE36 -> 51568.06 | L34: =SmtRes!DB36 -> 28878.11 | M34: =ROUND(ROUND(L34*Source!I36, 6)*1, 2) -> 8663.43 | N34: =SmtRes!AA36 -> 51568.06 | O34: =ROUND(ROUND(L34*Source!I36, 6)*SmtRes!DA36, 2) -> 8663.43 | P34: =SmtRes!AG36 -> 0 | Q34: =SmtRes!DC36 -> 0 | R34: =ROUND(ROUND(Q34*Source!I36, 6)*1, 2) -> 0 | S34: =SmtRes!AC36 -> 0 | T34: =ROUND(ROUND(Q34*Source!I36, 6)*SmtRes!AK36, 2) -> 0 | U34: 3 | Z34: =SmtRes!X36 -> -480916634 | AA34: 1531175116 | AB34: 1531175116
A35: =Source!A69 -> 4 | B35: 69 | G35: =Source!G69 -> Электрощит ЩАО (актовый зал)
A36: =Source!A107 -> 4 | B36: 107 | G36: =Source!G107 -> Электрощит ЩО (актовый зал)
A37: =Source!A145 -> 4 | B37: 145 | G37: =Source!G145 -> Электрощит РЩ (актовый зал)
A38: =Source!A183 -> 4 | B38: 183 | G38: =Source!G183 -> Помещение 108 Обеденный зал с умывальником
A39: =Source!A224 -> 4 | B39: 224 | G39: =Source!G224 -> Помещение 110 Кухня
A40: =Source!A263 -> 4 | B40: 263 | G40: =Source!G263 -> Помещение 111 Моечная
A41: =Source!A299 -> 4 | B41: 299 | G41: =Source!G299 -> Помещение 116 Душ
A42: =Source!A335 -> 4 | B42: 335 | G42: =Source!G335 -> Помещение 117 Коридор
...

Sheet Расчет стоимости ресурсов
A2: Ресурсная ведомость на
A3: =CONCATENATE("Объект: ",IF(Source!G3920<>"Новый объект", Source!G3920, "")) -> Объект: Электрика новая
A4: Обоснование | B4: Наименование | C4: Единица измерения | D4: Объем | E4: Базовая
E6: цена | F6: стоимость
A7: 1 | B7: 2 | C7: 3 | D7: 4 | E7: 5 | F7: 6
A8: =CONCATENATE("Локальная смета: ",IF(Source!G22<>"Новая локальная смета", Source!G22, "")) -> Локальная смета:
A9: =CONCATENATE("Раздел: ",IF(Source!G26<>"Новый раздел", Source!G26, "")) -> Раздел: Помещение 312 Актовый зал
A10: Материальные ресурсы
A11: 21.1-10-159 | B11: Сталь круглая и квадратная общего назначения углеродистая кипящая, марка Ст0, размер 5-12 мм | C11: т | D11: =ROUND(SUMIF(RV_DATA!AA8:AA34, 1531175116, RV_DATA!I8:I34), 6) -> 0.168 | E11: =ROUND(RV_DATA!K34, 6) -> 51568.06 | F11: =ROUND(SUMIF(RV_DATA!AA8:AA34, 1531175116, RV_DATA!M8:M34), 6) -> 8663.43 | Q11: 3
A12: 21.1-11-108 | B12: Шурупы-саморезы, размер 3,5х45 мм | C12: т | D12: =ROUND(SUMIF(RV_DATA!AA8:AA34, -2066596354, RV_DATA!I8:I34), 6) -> 0.002331 | E12: =ROUND(RV_DATA!K17, 6) -> 190540.34 | F12: =ROUND(SUMIF(RV_DATA!AA8:AA34, -2066596354, RV_DATA!M8:M34), 6) -> 444.15 | Q12: 3
A13: 21.1-11-133 | B13: Дюбель-гвоздь с патроном | C13: шт. | D13: =ROUND(SUMIF(RV_DATA!AA8:AA34, -503754449, RV_DATA!I8:I34), 6) -> 45.9 | E13: =ROUND(RV_DATA!K33, 6) -> 10.83 | F13: =ROUND(SUMIF(RV_DATA!AA8:AA34, -503754449, RV_DATA!M8:M34), 6) -> 497.1 | Q13: 3
A14: 21.1-11-198 | B14: Дюбели пластмассовые | C14: шт. | D14: =ROUND(SUMIF(RV_DATA!AA8:AA34, 798392207, RV_DATA!I8:I34), 6) -> 45.9 | E14: =ROUND(RV_DATA!K32, 6) -> 1.23 | F14: =ROUND(SUMIF(RV_DATA!AA8:AA34, 798392207, RV_DATA!M8:M34), 6) -> 56.46 | Q14: 3
A15: 21.1-11-21 | B15: Болты строительные черные с гайками и шайбами (10х100мм) | C15: т | D15: =ROUND(SUMIF(RV_DATA!AA8:AA34, -1191326009, RV_DATA!I8:I34), 6) -> 0.00312 | E15: =ROUND(RV_DATA!K31, 6) -> 161977.32 | F15: =ROUND(SUMIF(RV_DATA!AA8:AA34, -1191326009, RV_DATA!M8:M34), 6) -> 505.37 | Q15: 3
A16: 21.1-11-81 | B16: Патроны, калибр 6,8/11 М для дюбеля | C16: 100 шт. | D16: =ROUND(SUMIF(RV_DATA!AA8:AA34, -274985448, RV_DATA!I8:I34), 6) -> 12.6 | E16: =ROUND(RV_DATA!K16, 6) -> 997.35 | F16: =ROUND(SUMIF(RV_DATA!AA8:AA34, -274985448, RV_DATA!M8:M34), 6) -> 12566.61 | Q16: 3
A17: 21.1-20-10 | B17: Лента изоляционная хлопчатобумажная | C17: кг | D17: =ROUND(SUMIF(RV_DATA!AA8:AA34, -1596111638, RV_DATA!I8:I34), 6) -> 0.63 | E17: =ROUND(RV_DATA!K24, 6) -> 363.22 | F17: =ROUND(SUMIF(RV_DATA!AA8:AA34, -1596111638, RV_DATA!M8:M34), 6) -> 228.85 | Q17: 3
A18: 21.1-23-9 | B18: Электроды, тип Э-42, 46, 50, диаметр 4 - 6 мм | C18: т | D18: =ROUND(SUMIF(RV_DATA!AA8:AA34, 1948239711, RV_DATA!I8:I34), 6) -> 0.00063 | E18: =ROUND(RV_DATA!K29, 6) -> 109992.36 | F18: =ROUND(SUMIF(RV_DATA!AA8:AA34, 1948239711, RV_DATA!M8:M34), 6) -> 69.29 | Q18: 3
A19: 21.1-25-1027 | B19: Кабель-каналы, размер 60х40 мм: кабель-каналы | C19: м | D19: =ROUND(SUMIF(RV_DATA!AA8:AA34, -402984879, RV_DATA!I8:I34), 6) -> 315 | E19: =ROUND(RV_DATA!K15, 6) -> 138.94 | F19: =ROUND(SUMIF(RV_DATA!AA8:AA34, -402984879, RV_DATA!M8:M34), 6) -> 43766.1 | Q19: 3
A20: 21.1-25-1028 | B20: Кабель-каналы, размер 60х40 мм: заглушки | C20: шт. | D20: =ROUND(SUMIF(RV_DATA!AA8:AA34, 368106192, RV_DATA!I8:I34), 6) -> 47.25 | E20: =ROUND(RV_DATA!K14, 6) -> 145.46 | F20: =ROUND(SUMIF(RV_DATA!AA8:AA34, 368106192, RV_DATA!M8:M34), 6) -> 6872.99 | Q20: 3
A21: 21.1-25-1029 | B21: Кабель-каналы, размер 60х40 мм: накладки стыковые | C21: шт. | D21: =ROUND(SUMIF(RV_DATA!AA8:AA34, 1140495319, RV_DATA!I8:I34), 6) -> 12.6 | E21: =ROUND(RV_DATA!K13, 6) -> 126.89 | F21: =ROUND(SUMIF(RV_DATA!AA8:AA34, 1140495319, RV_DATA!M8:M34), 6) -> 1598.81 | Q21: 3
A22: 21.1-25-1031 | B22: Кабель-каналы, размер 60х40 мм: тройники | C22: шт. | D22: =ROUND(SUMIF(RV_DATA!AA8:AA34, -1841828503, RV_DATA!I8:I34), 6) -> 6.3 | E22: =ROUND(RV_DATA!K12, 6) -> 219.52 | F22: =ROUND(SUMIF(RV_DATA!AA8:AA34, -1841828503, RV_DATA!M8:M34), 6) -> 1382.98 | Q22: 3
A23: 21.1-25-1032 | B23: Кабель-каналы, размер 60х40 мм: углы внутренние | C23: шт. | D23: =ROUND(SUMIF(RV_DATA!AA8:AA34, -1064398607, RV_DATA!I8:I34), 6) -> 6.3 | E23: =ROUND(RV_DATA!K11, 6) -> 186.55 | F23: =ROUND(SUMIF(RV_DATA!AA8:AA34, -1064398607, RV_DATA!M8:M34), 6) -> 1175.27 | Q23: 3
A24: 21.1-25-1033 | B24: Кабель-каналы, размер 60х40 мм: углы наружные | C24: шт. | D24: =ROUND(SUMIF(RV_DATA!AA8:AA34, -124735961, RV_DATA!I8:I34), 6) -> 47.25 | E24: =ROUND(RV_DATA!K10, 6) -> 203.06 | F24: =ROUND(SUMIF(RV_DATA!AA8:AA34, -124735961, RV_DATA!M8:M34), 6) -> 9594.59 | Q24: 3
A25: 21.1-25-1034 | B25: Кабель-каналы, размер 60х40 мм: углы плоские | C25: шт. | D25: =ROUND(SUMIF(RV_DATA!AA8:AA34, 1614893387, RV_DATA!I8:I34), 6) -> 6.3 | E25: =ROUND(RV_DATA!K9, 6) -> 214.92 | F25: =ROUND(SUMIF(RV_DATA!AA8:AA34, 1614893387, RV_DATA!M8:M34), 6) -> 1354 | Q25: 3
A26: 21.1-6-37 | B26: Краски водно-дисперсионные поливинилацетатные, белые, марка ВД-ВА-17 | C26: т | D26: =ROUND(SUMIF(RV_DATA!AA8:AA34, 266707854, RV_DATA!I8:I34), 6) -> 0.0009 | E26: =ROUND(RV_DATA!K28, 6) -> 75121.86 | F26: =ROUND(SUMIF(RV_DATA!AA8:AA34, 266707854, RV_DATA!M8:M34), 6) -> 67.61 | Q26: 3
A27: 21.21-5-114 | B27: Лента монтажная, тип ЛМ-5 | C27: м | D27: =ROUND(SUMIF(RV_DATA!AA8:AA34, 193152040, RV_DATA!I8:I34), 6) -> 15.75 | E27: =ROUND(RV_DATA!K23, 6) -> 5.71 | F27: =ROUND(SUMIF(RV_DATA!AA8:AA34, 193152040, RV_DATA!M8:M34), 6) -> 89.93 | Q27: 3
A28: 21.21-5-2 | B28: Бирки маркировочные для кабелей и проводов, тип У153 У3,5 | C28: 1000 шт. | D28: =ROUND(SUMIF(RV_DATA!AA8:AA34, 299589489, RV_DATA!I8:I34), 6) -> 0.01575 | E28: =ROUND(RV_DATA!K22, 6) -> 718.56 | F28: =ROUND(SUMIF(RV_DATA!AA8:AA34, 299589489, RV_DATA!M8:M34), 6) -> 11.31 | Q28: 3
A29: 21.21-5-305 | B29: Сжимы, тип У731М для проводников магистральных сечением от 4 до 10 мм2 и ответвительных от 1,5 до 10 мм2 | C29: шт. | D29: =ROUND(SUMIF(RV_DATA!AA8:AA34, 1143219249, RV_DATA!I8:I34), 6) -> 31.5 | E29: =ROUND(RV_DATA!K21, 6) -> 29.36 | F29: =ROUND(SUMIF(RV_DATA!AA8:AA34, 1143219249, RV_DATA!M8:M34), 6) -> 924.84 | Q29: 3
A30: 21.21-5-342 | B30: Хомуты (стяжки) кабельные из полиамида, размеры 3,6х200 мм | C30: 100 шт. | D30: =ROUND(SUMIF(RV_DATA!AA8:AA34, -1533345047, RV_DATA!I8:I34), 6) -> 0.819 | E30: =ROUND(RV_DATA!K20, 6) -> 127.48 | F30: =ROUND(SUMIF(RV_DATA!AA8:AA34, -1533345047, RV_DATA!M8:M34), 6) -> 104.39 | Q30: 3
A31: 21.21-5-44 | B31: Кнопки для ленты ЛМ, тип 3,5 | C31: 1000 шт. | D31: =ROUND(SUMIF(RV_DATA!AA8:AA34, -2054620093, RV_DATA!I8:I34), 6) -> 0.063 | E31: =ROUND(RV_DATA!K19, 6) -> 258.44 | F31: =ROUND(SUMIF(RV_DATA!AA8:AA34, -2054620093, RV_DATA!M8:M34), 6) -> 16.29 | Q31: 3
A32: 21.23-13-14 | B32: Провода силовые с медными жилами в поливинилхлоридной изоляции, марка ПуГВ, номинальное напряжение до 450 В, число жил и сечение 1х6 мм2 | C32: км | D32: =ROUND(SUMIF(RV_DATA!AA8:AA34, -458052105, RV_DATA!I8:I34), 6) -> 0.32445 | E32: =ROUND(RV_DATA!K18, 6) -> 99643.05 | F32: =ROUND(SUMIF(RV_DATA!AA8:AA34, -458052105, RV_DATA!M8:M34), 6) -> 32329.17 | Q32: 3
A33: 21.23-8-258 | B33: Кабели силовые с медными жилами с поливинилхлоридной изоляцией в оболочке из поливинилхлоридного пластиката пониженной горючести, напряжение 660 В, марка ВВГнг(А), число жил и сечение, мм2: 1х 4 | C33: км | D33: =ROUND(SUMIF(RV_DATA!AA8:AA34, 249487062, RV_DATA!I8:I34), 6) -> 0.0108 | E33: =ROUND(RV_DATA!K27, 6) -> 47900.07 | F33: =ROUND(SUMIF(RV_DATA!AA8:AA34, 249487062, RV_DATA!M8:M34), 6) -> 517.32 | Q33: 3
A34: 21.23-8-270 | B34: Кабели силовые, с медными жилами, с изоляц. и оболоч.из ПВХ пластиката пониж.пожар.опасности, не распростр.горение, с пониж.дымо- и газовыделением и с низк.токсич-тью продуктов горения, напряж.1000 В, марка ВВГнг(А)-LSLTx, число жил и сечение, мм2: 3х2,5 | C34: км | D34: =ROUND(SUMIF(RV_DATA!AA8:AA34, 2094450950, RV_DATA!I8:I34), 6) -> 0.27 | E34: =ROUND(RV_DATA!K25, 6) -> 129532.62 | F34: =ROUND(SUMIF(RV_DATA!AA8:AA34, 2094450950, RV_DATA!M8:M34), 6) -> 34973.81 | Q34: 3
A35: 21.7-3-54 | B35: Сверло с алмазным покрытием, диаметр 6 мм | C35: шт. | D35: =ROUND(SUMIF(RV_DATA!AA8:AA34, -618828638, RV_DATA!I8:I34), 6) -> 12.6 | E35: =ROUND(RV_DATA!K8, 6) -> 1555.5 | F35: =ROUND(SUMIF(RV_DATA!AA8:AA34, -618828638, RV_DATA!M8:M34), 6) -> 19599.3 | Q35: 3
A36: 21.7-4-15 | B36: Профили стоек металлические для монтажа гипсовых перегородок и подвесных потолков стальные, оцинкованные, марка ПСЭ-2, сечение 50х35х0,55 мм | C36: т | D36: =ROUND(SUMIF(RV_DATA!AA8:AA34, 162372630, RV_DATA!I8:I34), 6) -> 0.0108 | E36: =ROUND(RV_DATA!K26, 6) -> 40246.74 | F36: =ROUND(SUMIF(RV_DATA!AA8:AA34, 162372630, RV_DATA!M8:M34), 6) -> 434.66 | Q36: 3
A37: Итого материальные ресурсы | E37: =SUMIF(Q11:Q36, 3, F11:F36) -> 177844.63
A38: =CONCATENATE("Раздел: ",IF(Source!G71<>"Новый раздел", Source!G71, "")) -> Раздел: Электрощит ЩАО (актовый зал)
A39: =CONCATENATE("Раздел: ",IF(Source!G109<>"Новый раздел", Source!G109, "")) -> Раздел: Электрощит ЩО (актовый зал)
A40: =CONCATENATE("Раздел: ",IF(Source!G147<>"Новый раздел", Source!G147, "")) -> Раздел: Электрощит РЩ (актовый зал)
A41: =CONCATENATE("Раздел: ",IF(Source!G185<>"Новый раздел", Source!G185, "")) -> Раздел: Помещение 108 Обеденный зал с умывальником
A42: =CONCATENATE("Раздел: ",IF(Source!G226<>"Новый раздел", Source!G226, "")) -> Раздел: Помещение 110 Кухня
...

Sheet Source
A1: 0 | B1: Smeta.RU (495) 974-1589 | D1: _PS_ | F1: 0 | G1: 0 | H1: 0 | I1: Smeta.RU | K1: 1 | L1: 54800 | M1: 10 | N1: 11 | O1: 15 | P1: 0 | Q1: 2
A12: 1 | B12: 3956 | C12: 0 | D12: =ROW(A3920) -> 3920 | E12: 0 | F12: Новый объект | G12: Электрика новая | I12: 0 | K12: 0 | L12: 0 | M12: 2 | O12: 0 | P12: 0 | Q12: 0 | R12: 108 | T12: 1 | V12: 0 | BB12: 0 | BH12: Сметные нормы списания | BI12: Коды ОКП для СН-2012 Выпуск № 6 (в ценах на 01.01.2026 г) | BJ12: 1 | BK12: 1 | BL12: 0 | BM12: 0 | BN12: 1 | BO12: 0 | BP12: 6 | BQ12: 2 | BR12: 1 | BS12: 1 | BT12: 0 | BU12: 0 | BV12: 1 | BW12: 0 | BX12: 0 | BY12: СН-2012 Выпуск № 6. (в ценах на 01.01.2026) глава_1-5, 7 | BZ12: Типовой расчет для СН-2012 Выпуск №6 (в ценах на 01.01.2026 г) | CA12: СН-2012 Выпуск № 6. База данных "Сборник стоимостных нормативов" в текущих ценах по состоянию на 01.01.2026 года | CB12: СН-2012 Выпуск № 6. База данных "Сборник стоимостных нормативов" в текущих ценах по состоянию на 01.01.2026 года | CC12: СН-2012 Выпуск № 6. База данных "Сборник стоимостных нормативов" в текущих ценах по состоянию на 01.01.2026 года | CD12: СН-2012 Выпуск № 6. База данных "Сборник стоимостных нормативов" в текущих ценах по состоянию на 01.01.2026 года | CE12: Поправки для СН-2012 Выпуск № 6 в ценах на 01.01.2026 г от 12.01.2026 | CF12: 0 | CG12: 0 | CH12: 2097160 | CK12: 0 | CY12: 0 | EC12: 0
A15: 15 | B15: 1
A18: 52 | B18: =B3920 -> 3956 | C18: =C3920 -> 1 | D18: =D3920 -> 12 | E18: =E3920 -> 0 | F18: =F3920 -> Новый объект | G18: =G3920 -> Электрика новая | O18: =O3920 -> 7348913 | P18: =P3920 -> 3554749.7 | Q18: =Q3920 -> 40402.55 | R18: =R3920 -> 5925.72 | S18: =S3920 -> 3753760.7 | T18: =T3920 -> 0 | U18: =U3920 -> 5228.5613 | V18: =V3920 -> 0 | ... GX18: =GX3920 -> 0
A20: 3 | B20: 1 | D20: =ROW(A3887) -> 3887 | F20: Новая локальная смета | G20: Новая локальная смета | I20: 0 | K20: 0 | L20: Новая локальная смета | S20: 0 | V20: 0 | BX20: 0 | CF20: 0 | CG20: 0
A22: 52 | B22: =B3887 -> 1 | C22: =C3887 -> 3 | D22: =D3887 -> 20 | E22: =E3887 -> 0 | F22: =F3887 -> Новая локальная смета | G22: =G3887 -> Новая локальная смета | O22: =O3887 -> 7348913 | P22: =P3887 -> 3554749.7 | Q22: =Q3887 -> 40402.55 | R22: =R3887 -> 5925.72 | S22: =S3887 -> 3753760.7 | T22: =T3887 -> 0 | U22: =U3887 -> 5228.5613 | V22: =V3887 -> 0 | ... GX22: =GX3887 -> 0
A24: 4 | B24: 1 | D24: =ROW(A39) -> 39 | F24: Новый раздел | G24: Помещение 312 Актовый зал | I24: 0 | K24: 0 | S24: 0 | V24: 0 | BX24: 0 | CJ24: 0
A26: 52 | B26: =B39 -> 1 | C26: =C39 -> 4 | D26: =D39 -> 24 | E26: =E39 -> 0 | F26: =F39 -> Новый раздел | G26: =G39 -> Помещение 312 Актовый зал | O26: =O39 -> 336394.13 | P26: =P39 -> 177844.64 | Q26: =Q39 -> 3050.01 | R26: =R39 -> 1434.4 | S26: =S39 -> 155499.48 | T26: =T39 -> 0 | U26: =U39 -> 258.213 | V26: =V39 -> 0 | ... GX26: =GX39 -> 0
A28: 17 | B28: 1 | C28: =ROW(SmtRes!A1) -> 1 | D28: =ROW(EtalonRes!A1) -> 1 | E28: 1 | F28: 1.21-3305-1-1/1 | G28: Демонтаж выключателей, розеток | H28: 100 шт. | I28: =ROUND(10/100,9) -> 0.1 | J28: 0 | K28: =ROUND(10/100,9) -> 0.1 | O28: =ROUND(CP28,2) -> 271.05 | P28: =ROUND(CQ28*I28,2) -> 0 | Q28: =ROUND(CR28*I28,2) -> 0 | R28: =ROUND(CS28*I28,2) -> 0 | S28: =ROUND(CT28*I28,2) -> 271.05 | T28: =ROUND(CU28*I28,2) -> 0 | U28: =CV28*I28 -> 0.584 | V28: =CW28*I28 -> 0 | W28: =ROUND(CX28*I28,2) -> 0 | X28: =ROUND(CY28,2) -> 189.74 | Y28: =ROUND(CZ28,2) -> 27.11 | AA28: 35364244 | AB28: =ROUND((AC28+AD28+AF28),6) -> 2710.46 | AC28: =ROUND((ES28),6) -> 0 | AD28: =ROUND((((ET28)-(EU28))+AE28),6) -> 0 | AE28: =ROUND((EU28),6) -> 0 | AF28: =ROUND((EV28),6) -> 2710.46 | AG28: =ROUND((AP28),6) -> 0 | AH28: =(EW28) -> 5.84 | AI28: =(EX28) -> 0 | AJ28: =(AS28) -> 0 | AK28: 2710.46 | AL28: 0 | AM28: 0 | AN28: 0 | AO28: 2710.46 | AP28: 0 | AQ28: 5.84 | AR28: 0 | AS28: 0 | AT28: 70 | AU28: 10 | AV28: 1 | AW28: 1 | AZ28: 1 | BA28: 1 | BB28: 1 | BC28: 1 | BH28: 0 | BI28: 4 | BJ28: СН-2012.1 Выпуск № 6 (в текущих ценах по состоянию на 01.01.2026 г.). 1.21-3305-1-1/1 | BM28: 0 | BN28: 0 | BP28: 0 | BQ28: 1 | BR28: 0 | BS28: 1 | BT28: 1 | BU28: 1 | BV28: 1 | BW28: 1 | BX28: 1 | BZ28: 70 | CA28: 10 | CE28: 0 | CF28: 0 | CG28: 0 | CM28: 0 | CO28: 0 | CP28: =(P28+Q28+S28) -> 271.05 | CQ28: =(AC28*BC28*AW28) -> 0 | CR28: =((((ET28)*BB28-(EU28)*BS28)+AE28*BS28)*AV28) -> 0 | CS28: =(AE28*BS28*AV28) -> 0 | CT28: =(AF28*BA28*AV28) -> 2710.46 | CU28: =AG28 -> 0 | CV28: =(AH28*AV28) -> 5.84 | CW28: =AI28 -> 0 | CX28: =AJ28 -> 0 | CY28: =((S28*BZ28)/100) -> 189.735 | CZ28: =((S28*CA28)/100) -> 27.105 | DN28: 0 | DO28: 0 | DP28: 1 | DQ28: 1 | DU28: 1010 | DV28: 100 шт. | DW28: 100 шт. | DX28: 100 | EE28: 35096056 | EF28: 1 | EG28: СН-2012 | EH28: 0 | EJ28: 4 | EK28: 0 | EL28: Подрядные работы, гл. 1-5,7 | EM28: работа | EQ28: 0 | ER28: 2710.46 | ES28: 0 | ET28: 0 | EU28: 0 | EV28: 2710.46 | EW28: 5.84 | EX28: 0 | EY28: 0 | FQ28: 0 | FR28: 0 | FS28: 0 | FX28: 70 | FY28: 10 | GD28: 0 | GF28: -931379651 | GG28: 2 | GH28: 1 | GI28: -2 | GJ28: 0 | GK28: =ROUND(R28*(R12)/100,2) -> 0 | GL28: =ROUND(IF(AND(BH28=3,BI28=3,FS28<>0),P28,0),2) -> 0 | GM28: =ROUND(O28+X28+Y28+GK28,2)+GX28 -> 487.9 | GN28: =IF(OR(BI28=0,BI28=1),GM28-GX28,0) -> 0 | GO28: =IF(BI28=2,GM28-GX28,0) -> 0 | GP28: =IF(BI28=4,GM28-GX28,0) -> 487.9 | GR28: 0 | GS28: 3 | GT28: 0 | GV28: =ROUND((GT28),6) -> 0 | GW28: 1 | GX28: =ROUND(HC28*I28,2) -> 0 | HA28: 0 | HB28: 0 | HC28: =GV28*GW28 -> 0 | HS28: 0 | IK28: 0
A29: 17 | B29: 1 | C29: =ROW(SmtRes!A14) -> 14 | D29: =ROW(EtalonRes!A14) -> 14 | E29: 2 | F29: 1.21-3103-31-2/3 | G29: Прокладка пластикового кабель-канала - по бетонному основанию / сечение 60х40 мм | H29: 100 м | I29: =ROUND(315/100,9) -> 3.15 | J29: 0 | K29: =ROUND(315/100,9) -> 3.15 | O29: =ROUND(CP29,2) -> 182312.64 | P29: =ROUND(CQ29*I29,2) -> 98354.78 | Q29: =ROUND(CR29*I29,2) -> 212.31 | R29: =ROUND(CS29*I29,2) -> 2.93 | S29: =ROUND(CT29*I29,2) -> 83745.55 | T29: =ROUND(CU29*I29,2) -> 0 | U29: =CV29*I29 -> 147.357 | V29: =CW29*I29 -> 0 | W29: =ROUND(CX29*I29,2) -> 0 | X29: =ROUND(CY29,2) -> 58621.89 | Y29: =ROUND(CZ29,2) -> 8374.56 | AA29: 35364244 | AB29: =ROUND((AC29+AD29+AF29),6) -> 57877.03 | AC29: =ROUND((ES29),6) -> 31223.74 | AD29: =ROUND((((ET29)-(EU29))+AE29),6) -> 67.4 | AE29: =ROUND((EU29),6) -> 0.93 | AF29: =ROUND((EV29),6) -> 26585.89 | AG29: =ROUND((AP29),6) -> 0 | AH29: =(EW29) -> 46.78 | AI29: =(EX29) -> 0 | AJ29: =(AS29) -> 0 | AK29: 57877.03 | AL29: 31223.74 | AM29: 67.4 | AN29: 0.93 | AO29: 26585.89 | AP29: 0 | AQ29: 46.78 | AR29: 0 | AS29: 0 | AT29: 70 | AU29: 10 | AV29: 1 | AW29: 1 | AZ29: 1 | BA29: 1 | BB29: 1 | BC29: 1 | BH29: 0 | BI29: 4 | BJ29: СН-2012.1 Выпуск № 6 (в текущих ценах по состоянию на 01.01.2026 г.). 1.21-3103-31-2/3 | BM29: 0 | BN29: 0 | BP29: 0 | BQ29: 1 | BR29: 0 | BS29: 1 | BT29: 1 | BU29: 1 | BV29: 1 | BW29: 1 | BX29: 1 | BZ29: 70 | CA29: 10 | CE29: 0 | CF29: 0 | CG29: 0 | CM29: 0 | CO29: 0 | CP29: =(P29+Q29+S29) -> 182312.64 | CQ29: =(AC29*BC29*AW29) -> 31223.74 | CR29: =((((ET29)*BB29-(EU29)*BS29)+AE29*BS29)*AV29) -> 67.4 | CS29: =(AE29*BS29*AV29) -> 0.93 | CT29: =(AF29*BA29*AV29) -> 26585.89 | CU29: =AG29 -> 0 | CV29: =(AH29*AV29) -> 46.78 | CW29: =AI29 -> 0 | CX29: =AJ29 -> 0 | CY29: =((S29*BZ29)/100) -> 58621.885 | CZ29: =((S29*CA29)/100) -> 8374.555 | DN29: 0 | DO29: 0 | DP29: 1 | DQ29: 1 | DU29: 1003 | DV29: 100 м | DW29: 100 м | DX29: 100 | EE29: 35096056 | EF29: 1 | EG29: СН-2012 | EH29: 0 | EJ29: 4 | EK29: 0 | EL29: Подрядные работы, гл. 1-5,7 | EM29: работа | EQ29: 0 | ER29: 57877.03 | ES29: 31223.74 | ET29: 67.4 | EU29: 0.93 | EV29: 26585.89 | EW29: 46.78 | EX29: 0 | EY29: 0 | FQ29: 0 | FR29: 0 | FS29: 0 | FX29: 70 | FY29: 10 | GD29: 0 | GF29: -236507790 | GG29: 2 | GH29: 1 | GI29: -2 | GJ29: 0 | GK29: =ROUND(R29*(R12)/100,2) -> 3.16 | GL29: =ROUND(IF(AND(BH29=3,BI29=3,FS29<>0),P29,0),2) -> 0 | GM29: =ROUND(O29+X29+Y29+GK29,2)+GX29 -> 249312.25 | GN29: =IF(OR(BI29=0,BI29=1),GM29-GX29,0) -> 0 | GO29: =IF(BI29=2,GM29-GX29,0) -> 0 | GP29: =IF(BI29=4,GM29-GX29,0) -> 249312.25 | GR29: 0 | GS29: 3 | GT29: 0 | GV29: =ROUND((GT29),6) -> 0 | GW29: 1 | GX29: =ROUND(HC29*I29,2) -> 0 | HA29: 0 | HB29: 0 | HC29: =GV29*GW29 -> 0 | HS29: 0 | IK29: 0
A30: 17 | B30: 1 | C30: =ROW(SmtRes!A23) -> 23 | D30: =ROW(EtalonRes!A23) -> 23 | E30: 3 | F30: 1.21-3103-7-1/1 | G30: Прокладка проводов и кабелей в лотках, провод сечением до 6 мм2 | H30: 100 м | I30: =ROUND(315/100,9) -> 3.15 | J30: 0 | K30: =ROUND(315/100,9) -> 3.15 | O30: =ROUND(CP30,2) -> 38734.1 | P30: =ROUND(CQ30*I30,2) -> 33659.04 | Q30: =ROUND(CR30*I30,2) -> 2808.51 | R30: =ROUND(CS30*I30,2) -> 1431.2 | S30: =ROUND(CT30*I30,2) -> 2266.55 | T30: =ROUND(CU30*I30,2) -> 0 | U30: =CV30*I30 -> 3.717 | V30: =CW30*I30 -> 0 | W30: =ROUND(CX30*I30,2) -> 0 | X30: =ROUND(CY30,2) -> 1586.59 | Y30: =ROUND(CZ30,2) -> 226.66 | AA30: 35364244 | AB30: =ROUND((AC30+AD30+AF30),6) -> 12296.54 | AC30: =ROUND((ES30),6) -> 10685.41 | AD30: =ROUND((((ET30)-(EU30))+AE30),6) -> 891.59 | AE30: =ROUND((EU30),6) -> 454.35 | AF30: =ROUND((EV30),6) -> 719.54 | AG30: =ROUND((AP30),6) -> 0 | AH30: =(EW30) -> 1.18 | AI30: =(EX30) -> 0 | AJ30: =(AS30) -> 0 | AK30: 12296.54 | AL30: 10685.41 | AM30: 891.59 | AN30: 454.35 | AO30: 719.54 | AP30: 0 | AQ30: 1.18 | AR30: 0 | AS30: 0 | AT30: 70 | AU30: 10 | AV30: 1 | AW30: 1 | AZ30: 1 | BA30: 1 | BB30: 1 | BC30: 1 | BH30: 0 | BI30: 4 | BJ30: СН-2012.1 Выпуск № 6 (в текущих ценах по состоянию на 01.01.2026 г.). 1.21-3103-7-1/1 | BM30: 0 | BN30: 0 | BP30: 0 | BQ30: 1 | BR30: 0 | BS30: 1 | BT30: 1 | BU30: 1 | BV30: 1 | BW30: 1 | BX30: 1 | BZ30: 70 | CA30: 10 | CE30: 0 | CF30: 0 | CG30: 0 | CM30: 0 | CO30: 0 | CP30: =(P30+Q30+S30) -> 38734.1 | CQ30: =(AC30*BC30*AW30) -> 10685.41 | CR30: =((((ET30)*BB30-(EU30)*BS30)+AE30*BS30)*AV30) -> 891.59 | CS30: =(AE30*BS30*AV30) -> 454.35 | CT30: =(AF30*BA30*AV30) -> 719.54 | CU30: =AG30 -> 0 | CV30: =(AH30*AV30) -> 1.18 | CW30: =AI30 -> 0 | CX30: =AJ30 -> 0 | CY30: =((S30*BZ30)/100) -> 1586.585 | CZ30: =((S30*CA30)/100) -> 226.655 | DN30: 0 | DO30: 0 | DP30: 1 | DQ30: 1 | DU30: 1003 | DV30: 100 м | DW30: 100 м | DX30: 100 | EE30: 35096056 | EF30: 1 | EG30: СН-2012 | EH30: 0 | EJ30: 4 | EK30: 0 | EL30: Подрядные работы, гл. 1-5,7 | EM30: работа | EQ30: 0 | ER30: 12296.54 | ES30: 10685.41 | ET30: 891.59 | EU30: 454.35 | EV30: 719.54 | EW30: 1.18 | EX30: 0 | EY30: 0 | FQ30: 0 | FR30: 0 | FS30: 0 | FX30: 70 | FY30: 10 | GD30: 0 | GF30: 1756020469 | GG30: 2 | GH30: 1 | GI30: -2 | GJ30: 0 | GK30: =ROUND(R30*(R12)/100,2) -> 1545.7 | GL30: =ROUND(IF(AND(BH30=3,BI30=3,FS30<>0),P30,0),2) -> 0 | GM30: =ROUND(O30+X30+Y30+GK30,2)+GX30 -> 42093.05 | GN30: =IF(OR(BI30=0,BI30=1),GM30-GX30,0) -> 0 | GO30: =IF(BI30=2,GM30-GX30,0) -> 0 | GP30: =IF(BI30=4,GM30-GX30,0) -> 42093.05 | GR30: 0 | GS30: 3 | GT30: 0 | GV30: =ROUND((GT30),6) -> 0 | GW30: 1 | GX30: =ROUND(HC30*I30,2) -> 0 | HA30: 0 | HB30: 0 | HC30: =GV30*GW30 -> 0 | HS30: 0 | IK30: 0
A31: 17 | B31: 1 | E31: 4 | F31: 21.23-8-270 | G31: Кабели силовые, с медными жилами, с изоляц. и оболоч.из ПВХ пластиката пониж.пожар.опасности, не распростр.горение, с пониж.дымо- и газовыделением и с низк.токсич-тью продуктов горения, напряж.1000 В, марка ВВГнг(А)-LSLTx, число жил и сечение, мм2: 3х2,5 | H31: км | I31: 0.27 | J31: 0 | K31: 0.27 | O31: =ROUND(CP31,2) -> 34973.81 | P31: =ROUND(CQ31*I31,2) -> 34973.81 | Q31: =ROUND(CR31*I31,2) -> 0 | R31: =ROUND(CS31*I31,2) -> 0 | S31: =ROUND(CT31*I31,2) -> 0 | T31: =ROUND(CU31*I31,2) -> 0 | U31: =CV31*I31 -> 0 | V31: =CW31*I31 -> 0 | W31: =ROUND(CX31*I31,2) -> 0 | X31: =ROUND(CY31,2) -> 0 | Y31: =ROUND(CZ31,2) -> 0 | AA31: 35364244 | AB31: =ROUND((AC31+AD31+AF31),6) -> 129532.62 | AC31: =ROUND((ES31),6) -> 129532.62 | AD31: =ROUND((((ET31)-(EU31))+AE31),6) -> 0 | AE31: =ROUND((EU31),6) -> 0 | AF31: =ROUND((EV31),6) -> 0 | AG31: =ROUND((AP31),6) -> 0 | AH31: =(EW31) -> 0 | AI31: =(EX31) -> 0 | AJ31: =(AS31) -> 0 | AK31: 129532.62 | AL31: 129532.62 | AM31: 0 | AN31: 0 | AO31: 0 | AP31: 0 | AQ31: 0 | AR31: 0 | AS31: 0 | AT31: 70 | AU31: 10 | AV31: 1 | AW31: 1 | AZ31: 1 | BA31: 1 | BB31: 1 | BC31: 1 | BH31: 3 | BI31: 4 | BJ31: СН-2012.21 Выпуск № 6 (в текущих ценах по состоянию на 01.01.2026 г.). 21.23-8-270 | BM31: 0 | BN31: 0 | BP31: 0 | BQ31: 1 | BR31: 0 | BS31: 1 | BT31: 1 | BU31: 1 | BV31: 1 | BW31: 1 | BX31: 1 | BZ31: 70 | CA31: 10 | CE31: 0 | CF31: 0 | CG31: 0 | CM31: 0 | CO31: 0 | CP31: =(P31+Q31+S31) -> 34973.81 | CQ31: =(AC31*BC31*AW31) -> 129532.62 | CR31: =((((ET31)*BB31-(EU31)*BS31)+AE31*BS31)*AV31) -> 0 | CS31: =(AE31*BS31*AV31) -> 0 | CT31: =(AF31*BA31*AV31) -> 0 | CU31: =AG31 -> 0 | CV31: =(AH31*AV31) -> 0 | CW31: =AI31 -> 0 | CX31: =AJ31 -> 0 | CY31: =((S31*BZ31)/100) -> 0 | CZ31: =((S31*CA31)/100) -> 0 | DN31: 0 | DO31: 0 | DP31: 1 | DQ31: 1 | DU31: 1003 | DV31: км | DW31: км | DX31: 1000 | EE31: 35096056 | EF31: 1 | EG31: СН-2012 | EH31: 0 | EJ31: 4 | EK31: 0 | EL31: Подрядные работы, гл. 1-5,7 | EM31: работа | EQ31: 0 | ER31: 129532.62 | ES31: 129532.62 | ET31: 0 | EU31: 0 | EV31: 0 | EW31: 0 | EX31: 0 | EY31: 0 | FQ31: 0 | FR31: 0 | FS31: 0 | FX31: 70 | FY31: 10 | GD31: 0 | GF31: 7717958 | GG31: 2 | GH31: 1 | GI31: -2 | GJ31: 0 | GK31: =ROUND(R31*(R12)/100,2) -> 0 | GL31: =ROUND(IF(AND(BH31=3,BI31=3,FS31<>0),P31,0),2) -> 0 | GM31: =ROUND(O31+X31+Y31+GK31,2)+GX31 -> 34973.81 | GN31: =IF(OR(BI31=0,BI31=1),GM31-GX31,0) -> 0 | GO31: =IF(BI31=2,GM31-GX31,0) -> 0 | GP31: =IF(BI31=4,GM31-GX31,0) -> 34973.81 | GR31: 0 | GS31: 3 | GT31: 0 | GV31: =ROUND((GT31),6) -> 0 | GW31: 1 | GX31: =ROUND(HC31*I31,2) -> 0 | HA31: 0 | HB31: 0 | HC31: =GV31*GW31 -> 0 | HS31: 0 | IK31: 0
A32: 17 | B32: 1 | C32: =ROW(SmtRes!A25) -> 25 | D32: =ROW(EtalonRes!A25) -> 25 | E32: 5 | F32: 1.20-3103-1-8/1 | G32: Установка розетки штепсельной неутопленного типа при открытой проводке | H32: 100 шт. | I32: =ROUND(12/100,9) -> 0.12 | J32: 0 | K32: =ROUND(12/100,9) -> 0.12 | O32: =ROUND(CP32,2) -> 3349.92 | P32: =ROUND(CQ32*I32,2) -> 0 | Q32: =ROUND(CR32*I32,2) -> 3.91 | R32: =ROUND(CS32*I32,2) -> 0.08 | S32: =ROUND(CT32*I32,2) -> 3346.01 | T32: =ROUND(CU32*I32,2) -> 0 | U32: =CV32*I32 -> 5.1372 | V32: =CW32*I32 -> 0 | W32: =ROUND(CX32*I32,2) -> 0 | X32: =ROUND(CY32,2) -> 2342.21 | Y32: =ROUND(CZ32,2) -> 334.6 | AA32: 35364244 | AB32: =ROUND((AC32+AD32+AF32),6) -> 27916.01 | AC32: =ROUND((ES32),6) -> 0 | AD32: =ROUND((((ET32)-(EU32))+AE32),6) -> 32.57 | AE32: =ROUND((EU32),6) -> 0.69 | AF32: =ROUND((EV32),6) -> 27883.44 | AG32: =ROUND((AP32),6) -> 0 | AH32: =(EW32) -> 42.81 | AI32: =(EX32) -> 0 | AJ32: =(AS32) -> 0 | AK32: 27916.01 | AL32: 0 | AM32: 32.57 | AN32: 0.69 | AO32: 27883.44 | AP32: 0 | AQ32: 42.81 | AR32: 0 | AS32: 0 | AT32: 70 | AU32: 10 | AV32: 1 | AW32: 1 | AZ32: 1 | BA32: 1 | BB32: 1 | BC32: 1 | BH32: 0 | BI32: 4 | BJ32: СН-2012.1 Выпуск № 6 (в текущих ценах по состоянию на 01.01.2026 г.). 1.20-3103-1-8/1 | BM32: 0 | BN32: 0 | BP32: 0 | BQ32: 1 | BR32: 0 | BS32: 1 | BT32: 1 | BU32: 1 | BV32: 1 | BW32: 1 | BX32: 1 | BZ32: 70 | CA32: 10 | CE32: 0 | CF32: 0 | CG32: 0 | CM32: 0 | CO32: 0 | CP32: =(P32+Q32+S32) -> 3349.92 | CQ32: =(AC32*BC32*AW32) -> 0 | CR32: =((((ET32)*BB32-(EU32)*BS32)+AE32*BS32)*AV32) -> 32.57 | CS32: =(AE32*BS32*AV32) -> 0.69 | CT32: =(AF32*BA32*AV32) -> 27883.44 | CU32: =AG32 -> 0 | CV32: =(AH32*AV32) -> 42.81 | CW32: =AI32 -> 0 | CX32: =AJ32 -> 0 | CY32: =((S32*BZ32)/100) -> 2342.207 | CZ32: =((S32*CA32)/100) -> 334.601 | DN32: 0 | DO32: 0 | DP32: 1 | DQ32: 1 | DU32: 1010 | DV32: 100 шт. | DW32: 100 шт. | DX32: 100 | EE32: 35096056 | EF32: 1 | EG32: СН-2012 | EH32: 0 | EJ32: 4 | EK32: 0 | EL32: Подрядные работы, гл. 1-5,7 | EM32: работа | EQ32: 262144 | ER32: 27916.01 | ES32: 0 | ET32: 32.57 | EU32: 0.69 | EV32: 27883.44 | EW32: 42.81 | EX32: 0 | EY32: 0 | FQ32: 0 | FR32: 0 | FS32: 0 | FX32: 70 | FY32: 10 | GD32: 0 | GF32: 1394402761 | GG32: 2 | GH32: 1 | GI32: -2 | GJ32: 0 | GK32: =ROUND(R32*(R12)/100,2) -> 0.09 | GL32: =ROUND(IF(AND(BH32=3,BI32=3,FS32<>0),P32,0),2) -> 0 | GM32: =ROUND(O32+X32+Y32+GK32,2)+GX32 -> 6026.82 | GN32: =IF(OR(BI32=0,BI32=1),GM32-GX32,0) -> 0 | GO32: =IF(BI32=2,GM32-GX32,0) -> 0 | GP32: =IF(BI32=4,GM32-GX32,0) -> 6026.82 | GR32: 0 | GS32: 3 | GT32: 0 | GV32: =ROUND((GT32),6) -> 0 | GW32: 1 | GX32: =ROUND(HC32*I32,2) -> 0 | HA32: 0 | HB32: 0 | HC32: =GV32*GW32 -> 0 | HS32: 0 | IK32: 0
